Workbook

Sheet 성분
A1: 분류 | B1: 식 품 명 | C1: 비고 | D1: 열 량 | E1: 단백질 | F1: 탄수화물 | G1: 지방 | H1: 칼슘 | I1: 철 | J1: VIT-A | K1: VIT-B1 | L1: VIT-B2 | M1: NIACIN | N1: VIT-C | O1: 폐기율 | P1: 출처
A2: 감자류 | B2: 감자샐러드 | C2: 감자,샐러드 | D2: 143 | E2: 2.7 | F2: 11 | G2: 8.2 | H2: 19 | I2: 0.7 | J2: 33 | K2: 0.08 | L2: 0.06 | M2: 정소예 | N2: 10 | O2: 0 | P2: 한국영양학회7차개정판(2000/10/31)
A3: 감자류 | B3: 깐감자 | C3: 감자,폐기율0% | D3: 120 | E3: 1 | F3: 14 | G3: 0.09 | H3: 6 | I3: 0.5 | J3: 0 | K3: 0.01 | L3: 0.01 | M3: 0.29 | N3: 3 | O3: 0 | P3: 한국영양학회7차개정판(2000/10/31)
A4: 감자류 | B4: 감자 | C4: 감자,생것 | D4: 130 | E4: 2.5 | F4: 14 | G4: 0.09 | H4: 6 | I4: 0.8 | J4: 0 | K4: 0.08 | L4: 0.03 | M4: 1.3 | N4: 21 | O4: 7 | P4: 한국영양학회7차개정판(2000/10/31)
A5: 감자류 | B5: 스마일감자 | C5: 감자튀긴것,패스트푸드 | D5: 523 | E5: 6.4 | F5: 62 | G5: 4.4 | H5: 24 | I5: 1.2 | J5: 0 | K5: 0.15 | L5: 0.02 | M5: 4.2 | N5: 42 | O5: 0 | P5: 한국영양학회7차개정판(2000/10/31)
B6: 맛감자 | C6: 감자튀긴것,패스트푸드 | D6: 523 | E6: 6.4 | F6: 62 | G6: 6.5 | H6: 24 | I6: 1.2 | J6: 0 | K6: 0.15 | L6: 0.02 | M6: 4.2 | N6: 42 | O6: 0 | P6: 한국영양학회7차개정판(2000/10/32)
B7: 감자반 | C7: 감자튀긴것,패스트푸드 | D7: 523 | E7: 6.4 | F7: 38 | G7: 0.4 | H7: 24 | I7: 1.2 | J7: 0 | K7: 0.15 | L7: 0.02 | M7: 4.2 | N7: 42 | O7: 0 | P7: 한국영양학회7차개정판(2000/10/32)
A8: 감자류 | B8: 해시브라운 | C8: 감자튀긴것,패스트푸드 | D8: 218 | E8: 5.1 | F8: 29 | G8: 13.9 | H8: 28 | I8: 1 | J8: 0 | K8: 0.11 | L8: 0.01 | M8: 3.4 | N8: 40 | O8: 0 | P8: 한국영양학회7차개정판(2000/10/32)
A9: 감자류 | B9: 고구마샐러드 | C9: 고구마 | D9: 214 | E9: 1.4 | F9: 31 | G9: 0.19 | H9: 24 | I9: 0.5 | J9: 19 | K9: 0.06 | L9: 0.05 | M9: 0.7 | N9: 25 | O9: 7 | P9: 한국영양학회7차개정판(2000/10/31)
A10: 감자류 | B10: 고구마 | C10: 고구마,생것 | D10: 128 | E10: 1.4 | F10: 31 | G10: 0.19 | H10: 24 | I10: 0.5 | J10: 19 | K10: 0.06 | L10: 0.05 | M10: 0.7 | N10: 25 | O10: 7 | P10: 한국영양학회7차개정판(2000/10/31)
A11: 감자류 | B11: 곤약 | C11: 곤약생것, 국수형 | D11: 12 | E11: 0.2 | F11: 6 | G11: 0 | H11: 75 | I11: 0.5 | J11: 0 | K11: 0 | L11: 0 | M11: 0 | N11: 0 | O11: 0 | P11: 한국영양학회7차개정판(2000/10/31)
A12: 감자류 | B12: 알감자 | C12: 돼지감자 | D12: 69 | E12: 2.2 | F12: 14 | G12: 0.2 | H12: 13 | I12: 0.2 | J12: 0 | K12: 0.07 | L12: 0.05 | M12: 1.7 | N12: 12 | O12: 7 | P12: 한국영양학회7차개정판(2000/10/31)
A13: 감자류 | B13: 감자녹말 | C13: 전분 | D13: 332 | E13: 0.1 | F13: 82 | G13: 0.1 | H13: 22 | I13: 1.8 | J13: 0 | K13: 0 | L13: 0 | M13: 0 | N13: 0 | O13: 0 | P13: 한국영양학회7차개정판(2000/10/31)
A14: 감자류 | B14: 당면 | C14: 전분,당면 | D14: 349 | E14: 0.1 | F14: 85 | G14: 0.1 | H14: 47 | I14: 3 | J14: 0 | K14: 0.01 | L14: 0 | M14: 0 | N14: 0 | O14: 0 | P14: 한국영양학회7차개정판(2000/10/31)
B15: 납작당면 | C15: 전분, 당면 | D15: 349 | E15: 0.1 | F15: 85 | G15: 0.2 | H15: 47 | I15: 3 | J15: 0 | K15: 0.01 | L15: 0 | M15: 0 | N15: 0 | O15: 0
B16: 분모자 | C16: 전분, 당면 | D16: 190.4 | E16: 0.1 | F16: 85 | G16: 0.2 | H16: 47 | I16: 3 | J16: 0 | K16: 0.01 | L16: 0 | M16: 0 | N16: 0 | O16: 0
A17: 감자류 | B17: 밀녹말 | C17: 전분 | D17: 351 | E17: 0.2 | F17: 3 | G17: 0.2 | H17: 14 | I17: 0.6 | J17: 0 | K17: 0 | L17: 0 | M17: 0 | N17: 0 | O17: 0 | P17: 한국영양학회7차개정판(2000/10/31)
A18: 감자류 | B18: 쌀녹말 | C18: 전분 | D18: 366 | E18: 0.2 | F18: 3 | G18: 0.1 | H18: 29 | I18: 1.5 | J18: 0 | K18: 0 | L18: 0 | M18: 0 | N18: 0 | O18: 0 | P18: 한국영양학회7차개정판(2000/10/31)
A19: 감자류 | B19: 밀녹말 | C19: 건다시마 | D19: 351 | E19: 0.2 | F19: 3 | G19: 0.2 | H19: 14 | I19: 0.6 | J19: 0 | K19: 0 | L19: 0 | M19: 0 | N19: 0 | O19: 0 | P19: 한국영양학회7차개정판(2000/10/31)
A20: 감자류 | B20: 쌀녹말 | C20: 다시멸치 | D20: 366 | E20: 0.2 | F20: 3 | G20: 0.1 | H20: 29 | I20: 1.5 | J20: 0 | K20: 0 | L20: 0 | M20: 0 | N20: 0 | O20: 0 | P20: 한국영양학회7차개정판(2000/10/31)
A21: 감자류 | B21: 옥수수녹말 | C21: 전분 | D21: 358 | E21: 0.1 | F21: 3 | G21: 0.1 | H21: 5 | I21: 1.7 | J21: 0 | K21: 0 | L21: 0 | M21: 0.1 | N21: 0 | O21: 0 | P21: 한국영양학회7차개정판(2000/10/31)
A22: 감자류 | B22: 고구마녹말 | C22: 전분,고구마 | D22: 342 | E22: 0.1 | F22: 3 | G22: 0.1 | H22: 62 | I22: 2.6 | J22: 0 | K22: 0 | L22: 0 | M22: 0.1 | N22: 0 | O22: 0 | P22: 한국영양학회7차개정판(2000/10/31)
A23: 감자류 | B23: 삶은토란 | C23: 토란삶은것 | D23: 60 | E23: 2.9 | F23: 0 | G23: 0.1 | H23: 16 | I23: 0.5 | J23: 0 | K23: 0.06 | L23: 0.03 | M23: 0.5 | N23: 0 | O23: 0 | P23: 한국영양학회7차개정판(2000/10/31)
A24: 감자류 | B24: 토란 | C24: 토란생것 | D24: 40 | E24: 2.3 | F24: 15 | G24: 0 | H24: 18 | I24: 0.6 | J24: 0 | K24: 0.07 | L24: 0.01 | M24: 0.8 | N24: 9 | O24: 18 | P24: 한국영양학회7차개정판(2000/10/31)
A25: 감자류 | B25: 후렌치후라이 | C25: 패스트푸드 | D25: 309 | E25: 4 | F25: 107 | G25: 6.5 | H25: 16 | I25: 1.4 | J25: 2 | K25: 0.14 | L25: 0.04 | M25: 2.3 | N25: 5 | O25: 0 | P25: 한국영양학회7차개정판(2000/10/31)
A26: 감자류 | B26: 페스츄리 | C26: 패스트푸드 | D26: 309 | E26: 4 | F26: 53 | G26: 19.5 | H26: 16 | I26: 1.4 | J26: 2 | K26: 0.14 | L26: 0.04 | M26: 2.3 | N26: 5 | O26: 0 | P26: 한국영양학회7차개정판(2000/10/31)
B27: 마늘빵 | C27: 빵류 | D27: 297 | E27: 7.5 | F27: 68 | G27: 27.9 | H27: 35 | I27: 0.5 | J27: 24 | K27: 0.12 | L27: 0.04 | M27: 2.3 | N27: 5 | O27: 0 | P27: 한국영양학회7차개정판(2000/10/31)
B28: 바게트 | C28: 빵류 | D28: 297 | E28: 7.5 | F28: 0 | G28: 27.9 | H28: 35 | I28: 0.5 | J28: 24 | K28: 0.12 | L28: 0.04 | M28: 2.3 | N28: 5 | O28: 0
A29: 곡류 | B29: 소보루빵 | C29: 빵류 | D29: 376 | E29: 8.8 | F29: 56.5 | G29: 13.2 | H29: 36 | I29: 0.7 | J29: 29 | K29: 0.14 | L29: 0.06 | M29: 1.3 | N29: 0 | O29: 0 | P29: 한국영양학회7차개정판(2000/10/31)
A30: 곡류 | B30: 미니롤 | C30: 빵 | D30: 323 | E30: 6.7 | F30: 48.6 | G30: 5.1 | H30: 44 | I30: 1.2 | J30: 60 | K30: 0.05 | L30: 0.08 | N30: 0 | O30: 0 | P30: 한국영양학회7차개정판(2000/10/31)
A31: 곡류 | B31: 도지마롤케이크 | C31: 빵 | D31: 150 | E31: 6.7 | F31: 48.6 | G31: 5.1 | H31: 44 | I31: 1.2 | J31: 60 | K31: 0.05 | L31: 0.08 | N31: 0 | O31: 0 | P31: 한국영양학회7차개정판(2000/10/31)
A32: 곡류 | B32: 메밀 | C32: 가루,도정곡 | D32: 359 | E32: 6.1 | F32: 69.6 | G32: 4 | H32: 10 | I32: 1.7 | J32: 0 | K32: 0.16 | L32: 0.07 | M32: 2.2 | N32: 0 | O32: 0 | P32: 한국영양학회7차개정판(2000/10/31)
A33: 곡류 | B33: 국수 | C33: 국수,마른것 | D33: 368 | E33: 11.7 | F33: 72.2 | G33: 1 | H33: 39 | I33: 2.1 | J33: 0 | K33: 0.17 | L33: 0.31 | M33: 1.4 | N33: 0 | O33: 0 | P33: 한국영양학회7차개정판(2000/10/31)
A34: 곡류 | B34: 시루떡 | C34: 떡 | D34: 205 | E34: 5.7 | F34: 47.5 | G34: 0.8 | H34: 19 | I34: 3.3 | J34: 0 | K34: 0.03 | L34: 0.02 | M34: 0.7 | N34: 0 | O34: 0 | P34: 한국영양학회7차개정판(2000/10/31)
A35: 곡류 | B35: 찹쌀떡 | C35: 떡 | D35: 236 | E35: 4.8 | F35: 50.4 | G35: 1.4 | H35: 15 | I35: 0.8 | J35: 0 | K35: 0.04 | L35: 0.01 | M35: 0.6 | N35: 0 | O35: 0 | P35: 한국영양학회7차개정판(2000/10/31)
A36: 곡류 | B36: 찹쌀떡 | C36: 식용유 | D36: 236 | E36: 4.8 | F36: 50.4 | G36: 1.4 | H36: 15 | I36: 0.8 | J36: 0 | K36: 0.04 | L36: 0.01 | M36: 0.6 | N36: 0 | O36: 0 | P36: 한국영양학회7차개정판(2000/10/31)
A37: 곡류 | B37: 찹쌀경단 | C37: 떡, | D37: 240 | E37: 4.1 | F37: 43.1 | G37: 1.8 | H37: 14 | I37: 0.8 | J37: 2 | K37: 0.03 | L37: 0.03 | M37: 0.6 | N37: 0 | O37: 0 | P37: 한국영양학회7차개정판(2000/10/31)
A38: 곡류 | B38: 찹쌀가루 | C38: 찹쌀가루 | D38: 378 | E38: 6.6 | F38: 86 | G38: 0.4 | H38: 12 | I38: 0.8 | J38: 0 | K38: 0.1 | L38: 0.02 | M38: 0 | N38: 0 | O38: 0 | P38: 한국영양학회7차개정판(2000/10/31)
A39: 곡류 | B39: 팥인절미 | C39: 떡, | D39: 208 | E39: 0 | F39: 44.8 | G39: 0.9 | H39: 16 | I39: 1.9 | J39: 0 | K39: 0.06 | L39: 0.02 | M39: 0.7 | N39: 0 | O39: 0 | P39: 한국영양학회7차개정판(2000/10/31)
A40: 곡류 | B40: 송편검정콩속 | C40: 떡,검정콩속 | D40: 202 | E40: 4.4 | F40: 41.2 | G40: 1 | H40: 32 | I40: 0 | J40: 0 | K40: 0.08 | L40: 0.09 | M40: 2.9 | N40: 0 | O40: 0 | P40: 한국영양학회7차개정판(2000/10/31)
...

Sheet 원본
N1: 업체담당 | O1: 교감
A3: 일 자 : | C3: 45726 | E3: 석식
A6: 급식학생수 | O6: 총계
A7: 구분 | D7: 1학년 | F7: 2학년 | H7: 3학년 | K7: 합계 | M7: 교직원
A8: 경북여자고등학교 | D8: 64 | F8: 29 | H8: 71 | K8: =SUM(D8:J8) -> 164 | O8: =SUM(K8:N8) -> 164
A9: 식 단 | D9: 백미밥,추억의도시락,얼큰어묵국,뿌리채소모듬맛탕,단배추겉절이,딸기타임
A10: 번호 | B10: 메뉴명 | C10: 식품명 | D10: 1인량 (g) | E10: 열량 (kcal) | F10: 탄수화물 (g) | G10: 단백질 (g) | H10: 지방 (g) | I10: 칼슘 (mg) | J10: 철 (mg) | K10: VIT-A (RE) | L10: VIT-B1 (mg) | M10: VIT-B2 (mg) | N10: NIACIN (mg) | O10: VIT-C | P10: 기준량 | Q10: 총량
A11: =ROW()-10 -> 1 | B11: 백미밥 | C11: 쌀 | D11: 70 | E11: =IF($C11="","",VLOOKUP($C11,성분!$B$2:$O$1509,3,FALSE))/100*P11 -> 168 | F11: =IF($C11="","",VLOOKUP($C11,성분!$B$2:$O$1509,5,FALSE))/100*$P11 -> 54.95 | G11: =IF($C11="","",VLOOKUP($C11,성분!$B$2:$O$1509,4,FALSE))/100*$P11 -> 4.48 | H11: =IF($C11="","",VLOOKUP($C11,성분!$B$2:$O$1509,6,FALSE))/100*$P11 -> 0.28 | I11: =IF($C11="","",VLOOKUP($C11,성분!$B$2:$O$1509,7,FALSE))/100*$P11 -> 4.9 | J11: =IF($C11="","",VLOOKUP($C11,성분!$B$2:$O$1509,8,FALSE))/100*$P11 -> 0.35 | K11: =IF($C11="","",VLOOKUP($C11,성분!$B$2:$O$1509,9,FALSE))/100*$P11 -> 0 | L11: =IF($C11="","",VLOOKUP($C11,성분!$B$2:$O$1509,10,FALSE))/100*$P11 -> 0.084 | M11: =IF($C11="","",VLOOKUP($C11,성분!$B$2:$O$1509,11,FALSE))/100*$P11 -> 0 | N11: =IF($C11="","",VLOOKUP($C11,성분!$B$2:$O$1509,12,FALSE))/100*$P11 -> 0.98 | O11: =IF($C11="","",VLOOKUP($C11,성분!$B$2:$O$1509,13,FALSE))/100*$P11 -> 0 | P11: =D11 -> 70 | Q11: =($O$8*P11)/1000 -> 11.48 | R11: =INT(Q11) -> 11
A12: =ROW()-10 -> 2 | B12: 추억의도시락 | C12: 옛날소시지 | D12: 50 | E12: =IF($C12="","",VLOOKUP($C12,성분!$B$2:$O$1509,3,FALSE))/100*P12 -> 102.5 | F12: =IF($C12="","",VLOOKUP($C12,성분!$B$2:$O$1509,5,FALSE))/100*$P12 -> 9.5 | G12: =IF($C12="","",VLOOKUP($C12,성분!$B$2:$O$1509,4,FALSE))/100*$P12 -> 2.5 | H12: =IF($C12="","",VLOOKUP($C12,성분!$B$2:$O$1509,6,FALSE))/100*$P12 -> 6 | I12: 0.92 | J12: =IF($C12="","",VLOOKUP($C12,성분!$B$2:$O$1509,8,FALSE))/100*$P12 -> 0 | K12: =IF($C12="","",VLOOKUP($C12,성분!$B$2:$O$1509,9,FALSE))/100*$P12 -> 0 | L12: =IF($C12="","",VLOOKUP($C12,성분!$B$2:$O$1509,10,FALSE))/100*$P12 -> 0 | M12: =IF($C12="","",VLOOKUP($C12,성분!$B$2:$O$1509,11,FALSE))/100*$P12 -> 0 | N12: =IF($C12="","",VLOOKUP($C12,성분!$B$2:$O$1509,12,FALSE))/100*$P12 -> 0 | O12: =IF($C12="","",VLOOKUP($C12,성분!$B$2:$O$1509,13,FALSE))/100*$P12 -> 0 | P12: =D12 -> 50 | Q12: =($O$8*P12)/1000 -> 8.2 | R12: =INT(Q12) -> 8
A13: =ROW()-10 -> 3 | C13: 계란후라이 | D13: 30 | E13: =IF($C13="","",VLOOKUP($C13,성분!$B$2:$O$1509,3,FALSE))/100*P13 -> 48.6 | F13: =IF($C13="","",VLOOKUP($C13,성분!$B$2:$O$1509,5,FALSE))/100*$P13 -> 8.4 | G13: 2.51 | H13: =IF($C13="","",VLOOKUP($C13,성분!$B$2:$O$1509,6,FALSE))/100*$P13 -> 2.904 | I13: 18.92 | J13: =IF($C13="","",VLOOKUP($C13,성분!$B$2:$O$1509,8,FALSE))/100*$P13 -> 0.6 | K13: =IF($C13="","",VLOOKUP($C13,성분!$B$2:$O$1509,9,FALSE))/100*$P13 -> 45 | L13: =IF($C13="","",VLOOKUP($C13,성분!$B$2:$O$1509,10,FALSE))/100*$P13 -> 0.018 | M13: =IF($C13="","",VLOOKUP($C13,성분!$B$2:$O$1509,11,FALSE))/100*$P13 -> 0.084 | N13: =IF($C13="","",VLOOKUP($C13,성분!$B$2:$O$1509,12,FALSE))/100*$P13 -> 0 | O13: =IF($C13="","",VLOOKUP($C13,성분!$B$2:$O$1509,13,FALSE))/100*$P13 -> 0 | P13: =D13 -> 30 | Q13: =($O$8*P13)/1000 -> 4.92 | R13: =INT(Q13) -> 4
A14: =ROW()-10 -> 4 | C14: 지리멸치 | D14: 4 | E14: =IF($C14="","",VLOOKUP($C14,성분!$B$2:$O$1509,3,FALSE))/100*P14 -> 10.8 | F14: =IF($C14="","",VLOOKUP($C14,성분!$B$2:$O$1509,5,FALSE))/100*$P14 -> 0.036 | G14: 1.11 | H14: =IF($C14="","",VLOOKUP($C14,성분!$B$2:$O$1509,6,FALSE))/100*$P14 -> 0.212 | I14: =IF($C14="","",VLOOKUP($C14,성분!$B$2:$O$1509,7,FALSE))/100*$P14 -> 73 | J14: =IF($C14="","",VLOOKUP($C14,성분!$B$2:$O$1509,8,FALSE))/100*$P14 -> 0.3 | K14: =IF($C14="","",VLOOKUP($C14,성분!$B$2:$O$1509,9,FALSE))/100*$P14 -> 0 | L14: =IF($C14="","",VLOOKUP($C14,성분!$B$2:$O$1509,10,FALSE))/100*$P14 -> 0.006 | M14: =IF($C14="","",VLOOKUP($C14,성분!$B$2:$O$1509,11,FALSE))/100*$P14 -> 0.0072 | N14: =IF($C14="","",VLOOKUP($C14,성분!$B$2:$O$1509,12,FALSE))/100*$P14 -> 0.464 | O14: =IF($C14="","",VLOOKUP($C14,성분!$B$2:$O$1509,13,FALSE))/100*$P14 -> 0 | P14: =D14 -> 4 | Q14: =($O$8*P14)/1000 -> 0.656 | R14: =INT(Q14) -> 0
A15: =ROW()-10 -> 5 | C15: 김가루 | D15: 5 | E15: =IF($C15="","",VLOOKUP($C15,성분!$B$2:$O$1509,3,FALSE))/100*P15 -> 13.6 | F15: =IF($C15="","",VLOOKUP($C15,성분!$B$2:$O$1509,5,FALSE))/100*$P15 -> 2.055 | G15: =IF($C15="","",VLOOKUP($C15,성분!$B$2:$O$1509,4,FALSE))/100*$P15 -> 1 | H15: =IF($C15="","",VLOOKUP($C15,성분!$B$2:$O$1509,6,FALSE))/100*$P15 -> 0.115 | I15: =IF($C15="","",VLOOKUP($C15,성분!$B$2:$O$1509,7,FALSE))/100*$P15 -> 20.5 | J15: =IF($C15="","",VLOOKUP($C15,성분!$B$2:$O$1509,8,FALSE))/100*$P15 -> 0.25 | K15: =IF($C15="","",VLOOKUP($C15,성분!$B$2:$O$1509,9,FALSE))/100*$P15 -> 12 | L15: =IF($C15="","",VLOOKUP($C15,성분!$B$2:$O$1509,10,FALSE))/100*$P15 -> 0.015 | M15: =IF($C15="","",VLOOKUP($C15,성분!$B$2:$O$1509,11,FALSE))/100*$P15 -> 0.005 | N15: =IF($C15="","",VLOOKUP($C15,성분!$B$2:$O$1509,12,FALSE))/100*$P15 -> 0.25 | O15: =IF($C15="","",VLOOKUP($C15,성분!$B$2:$O$1509,13,FALSE))/100*$P15 -> 1.85 | P15: =D15 -> 5 | Q15: =($O$8*P15)/1000 -> 0.82 | R15: =INT(Q15) -> 0
A16: =ROW()-10 -> 6 | C16: 맛김치 | D16: 45 | E16: =IF($C16="","",VLOOKUP($C16,성분!$B$2:$O$1509,3,FALSE))/100*P16 -> 22.5 | F16: =IF($C16="","",VLOOKUP($C16,성분!$B$2:$O$1509,5,FALSE))/100*$P16 -> 1.98 | G16: =IF($C16="","",VLOOKUP($C16,성분!$B$2:$O$1509,4,FALSE))/100*$P16 -> 0.9 | H16: =IF($C16="","",VLOOKUP($C16,성분!$B$2:$O$1509,6,FALSE))/100*$P16 -> 0.09 | I16: =IF($C16="","",VLOOKUP($C16,성분!$B$2:$O$1509,7,FALSE))/100*$P16 -> 21.15 | J16: 0.46 | K16: =IF($C16="","",VLOOKUP($C16,성분!$B$2:$O$1509,9,FALSE))/100*$P16 -> 21.6 | L16: =IF($C16="","",VLOOKUP($C16,성분!$B$2:$O$1509,10,FALSE))/100*$P16 -> 0.027 | M16: =IF($C16="","",VLOOKUP($C16,성분!$B$2:$O$1509,11,FALSE))/100*$P16 -> 0.027 | N16: =IF($C16="","",VLOOKUP($C16,성분!$B$2:$O$1509,12,FALSE))/100*$P16 -> 0.36 | O16: =IF($C16="","",VLOOKUP($C16,성분!$B$2:$O$1509,13,FALSE))/100*$P16 -> 6.3 | P16: =D16 -> 45 | Q16: =($O$8*P16)/1000 -> 7.38 | R16: =INT(Q16) -> 7
A17: =ROW()-10 -> 7 | C17: 검은콩조림 | D17: 15 | E17: 20.5 | F17: =IF($C17="","",VLOOKUP($C17,성분!$B$2:$O$1509,5,FALSE))/100*$P17 -> 5.85 | G17: 1.93 | H17: =IF($C17="","",VLOOKUP($C17,성분!$B$2:$O$1509,6,FALSE))/100*$P17 -> 0.6 | I17: =IF($C17="","",VLOOKUP($C17,성분!$B$2:$O$1509,7,FALSE))/100*$P17 -> 0 | J17: =IF($C17="","",VLOOKUP($C17,성분!$B$2:$O$1509,8,FALSE))/100*$P17 -> 0 | K17: =IF($C17="","",VLOOKUP($C17,성분!$B$2:$O$1509,9,FALSE))/100*$P17 -> 0 | L17: =IF($C17="","",VLOOKUP($C17,성분!$B$2:$O$1509,10,FALSE))/100*$P17 -> 0 | M17: =IF($C17="","",VLOOKUP($C17,성분!$B$2:$O$1509,11,FALSE))/100*$P17 -> 0 | N17: =IF($C17="","",VLOOKUP($C17,성분!$B$2:$O$1509,12,FALSE))/100*$P17 -> 0 | O17: =IF($C17="","",VLOOKUP($C17,성분!$B$2:$O$1509,13,FALSE))/100*$P17 -> 0 | P17: =D17 -> 15 | Q17: =($O$8*P17)/1000 -> 2.46 | R17: =INT(Q17) -> 2
A18: =ROW()-10 -> 8 | B18: 얼큰어묵국 | C18: 종합어묵 | D18: 28 | E18: =IF($C18="","",VLOOKUP($C18,성분!$B$2:$O$1509,3,FALSE))/100*P18 -> 61.6 | F18: =IF($C18="","",VLOOKUP($C18,성분!$B$2:$O$1509,5,FALSE))/100*$P18 -> 3.472 | G18: 1.2 | H18: =IF($C18="","",VLOOKUP($C18,성분!$B$2:$O$1509,6,FALSE))/100*$P18 -> 0.0532 | I18: =IF($C18="","",VLOOKUP($C18,성분!$B$2:$O$1509,7,FALSE))/100*$P18 -> 22.54 | J18: =IF($C18="","",VLOOKUP($C18,성분!$B$2:$O$1509,8,FALSE))/100*$P18 -> 0.364 | K18: =IF($C18="","",VLOOKUP($C18,성분!$B$2:$O$1509,9,FALSE))/100*$P18 -> 0 | L18: =IF($C18="","",VLOOKUP($C18,성분!$B$2:$O$1509,10,FALSE))/100*$P18 -> 0.028 | M18: =IF($C18="","",VLOOKUP($C18,성분!$B$2:$O$1509,11,FALSE))/100*$P18 -> 0.028 | N18: =IF($C18="","",VLOOKUP($C18,성분!$B$2:$O$1509,12,FALSE))/100*$P18 -> 0.0644 | O18: =IF($C18="","",VLOOKUP($C18,성분!$B$2:$O$1509,13,FALSE))/100*$P18 -> 0 | P18: =D18 -> 28 | Q18: =($O$8*P18)/1000 -> 4.592 | R18: =INT(Q18) -> 4
A19: =ROW()-10 -> 9 | C19: 무우 | D19: 20 | E19: =IF($C19="","",VLOOKUP($C19,성분!$B$2:$O$1509,3,FALSE))/100*P19 -> 3.6 | F19: =IF($C19="","",VLOOKUP($C19,성분!$B$2:$O$1509,5,FALSE))/100*$P19 -> 0.836 | G19: =IF($C19="","",VLOOKUP($C19,성분!$B$2:$O$1509,4,FALSE))/100*$P19 -> 0.16 | H19: =IF($C19="","",VLOOKUP($C19,성분!$B$2:$O$1509,6,FALSE))/100*$P19 -> 0.04 | I19: 7 | J19: =IF($C19="","",VLOOKUP($C19,성분!$B$2:$O$1509,8,FALSE))/100*$P19 -> 0.156 | K19: =IF($C19="","",VLOOKUP($C19,성분!$B$2:$O$1509,9,FALSE))/100*$P19 -> 3 | L19: =IF($C19="","",VLOOKUP($C19,성분!$B$2:$O$1509,10,FALSE))/100*$P19 -> 0.006 | M19: =IF($C19="","",VLOOKUP($C19,성분!$B$2:$O$1509,11,FALSE))/100*$P19 -> 0.012 | N19: =IF($C19="","",VLOOKUP($C19,성분!$B$2:$O$1509,12,FALSE))/100*$P19 -> 0.042 | O19: =IF($C19="","",VLOOKUP($C19,성분!$B$2:$O$1509,13,FALSE))/100*$P19 -> 0.64 | P19: =D19 -> 20 | Q19: =($O$8*P19)/1000 -> 3.28 | R19: =INT(Q19) -> 3
A20: =ROW()-10 -> 10 | C20: 대파 | D20: 3 | E20: =IF($C20="","",VLOOKUP($C20,성분!$B$2:$O$1509,3,FALSE))/100*P20 -> 0.78 | F20: =IF($C20="","",VLOOKUP($C20,성분!$B$2:$O$1509,5,FALSE))/100*$P20 -> 0.1338 | G20: =IF($C20="","",VLOOKUP($C20,성분!$B$2:$O$1509,4,FALSE))/100*$P20 -> 0 | H20: =IF($C20="","",VLOOKUP($C20,성분!$B$2:$O$1509,6,FALSE))/100*$P20 -> 0.0078 | I20: 3.43 | J20: =IF($C20="","",VLOOKUP($C20,성분!$B$2:$O$1509,8,FALSE))/100*$P20 -> 0.03 | K20: =IF($C20="","",VLOOKUP($C20,성분!$B$2:$O$1509,9,FALSE))/100*$P20 -> 3.87 | L20: =IF($C20="","",VLOOKUP($C20,성분!$B$2:$O$1509,10,FALSE))/100*$P20 -> 0.0018 | M20: =IF($C20="","",VLOOKUP($C20,성분!$B$2:$O$1509,11,FALSE))/100*$P20 -> 0.0027 | N20: =IF($C20="","",VLOOKUP($C20,성분!$B$2:$O$1509,12,FALSE))/100*$P20 -> 0.018 | O20: =IF($C20="","",VLOOKUP($C20,성분!$B$2:$O$1509,13,FALSE))/100*$P20 -> 0.63 | P20: =D20 -> 3 | Q20: =($O$8*P20)/1000 -> 0.492 | R20: =INT(Q20) -> 0
A21: =ROW()-10 -> 11 | C21: 건다시마 | D21: 1 | E21: =IF($C21="","",VLOOKUP($C21,성분!$B$2:$O$1509,3,FALSE))/100*P21 -> 1.89 | F21: =IF($C21="","",VLOOKUP($C21,성분!$B$2:$O$1509,5,FALSE))/100*$P21 -> 0.452 | G21: =IF($C21="","",VLOOKUP($C21,성분!$B$2:$O$1509,4,FALSE))/100*$P21 -> 0.074 | H21: =IF($C21="","",VLOOKUP($C21,성분!$B$2:$O$1509,6,FALSE))/100*$P21 -> 0.011 | I21: =IF($C21="","",VLOOKUP($C21,성분!$B$2:$O$1509,7,FALSE))/100*$P21 -> 7.08 | J21: =IF($C21="","",VLOOKUP($C21,성분!$B$2:$O$1509,8,FALSE))/100*$P21 -> 0.063 | K21: =IF($C21="","",VLOOKUP($C21,성분!$B$2:$O$1509,9,FALSE))/100*$P21 -> 0.96 | L21: =IF($C21="","",VLOOKUP($C21,성분!$B$2:$O$1509,10,FALSE))/100*$P21 -> 0.0022 | M21: =IF($C21="","",VLOOKUP($C21,성분!$B$2:$O$1509,11,FALSE))/100*$P21 -> 0.0045 | N21: =IF($C21="","",VLOOKUP($C21,성분!$B$2:$O$1509,12,FALSE))/100*$P21 -> 0.045 | O21: =IF($C21="","",VLOOKUP($C21,성분!$B$2:$O$1509,13,FALSE))/100*$P21 -> 0.18 | P21: =D21 -> 1 | Q21: =($O$8*P21)/1000 -> 0.164 | R21: =INT(Q21) -> 0
A22: =ROW()-10 -> 12 | C22: 다시멸치 | D22: 1 | E22: =IF($C22="","",VLOOKUP($C22,성분!$B$2:$O$1509,3,FALSE))/100*P22 -> 3.03 | F22: =IF($C22="","",VLOOKUP($C22,성분!$B$2:$O$1509,5,FALSE))/100*$P22 -> 0.003 | G22: =IF($C22="","",VLOOKUP($C22,성분!$B$2:$O$1509,4,FALSE))/100*$P22 -> 0.33 | H22: =IF($C22="","",VLOOKUP($C22,성분!$B$2:$O$1509,6,FALSE))/100*$P22 -> 0.073 | I22: =IF($C22="","",VLOOKUP($C22,성분!$B$2:$O$1509,7,FALSE))/100*$P22 -> 17 | J22: =IF($C22="","",VLOOKUP($C22,성분!$B$2:$O$1509,8,FALSE))/100*$P22 -> 0.04 | K22: =IF($C22="","",VLOOKUP($C22,성분!$B$2:$O$1509,9,FALSE))/100*$P22 -> 0 | L22: =IF($C22="","",VLOOKUP($C22,성분!$B$2:$O$1509,10,FALSE))/100*$P22 -> 0.0014 | M22: =IF($C22="","",VLOOKUP($C22,성분!$B$2:$O$1509,11,FALSE))/100*$P22 -> 0.0012 | N22: =IF($C22="","",VLOOKUP($C22,성분!$B$2:$O$1509,12,FALSE))/100*$P22 -> 0.02 | O22: =IF($C22="","",VLOOKUP($C22,성분!$B$2:$O$1509,13,FALSE))/100*$P22 -> 0 | P22: =D22 -> 1 | Q22: =($O$8*P22)/1000 -> 0.164 | R22: =INT(Q22) -> 0
A23: =ROW()-10 -> 13 | B23: 뿌리채소모듬맛탕 | C23: 통살콘오징어너겟 | D23: 50 | E23: =IF($C23="","",VLOOKUP($C23,성분!$B$2:$O$1509,3,FALSE))/100*P23 -> 50 | F23: =IF($C23="","",VLOOKUP($C23,성분!$B$2:$O$1509,5,FALSE))/100*$P23 -> 10 | G23: =IF($C23="","",VLOOKUP($C23,성분!$B$2:$O$1509,4,FALSE))/100*$P23 -> 10 | H23: =IF($C23="","",VLOOKUP($C23,성분!$B$2:$O$1509,6,FALSE))/100*$P23 -> 15 | I23: 14.85 | J23: =IF($C23="","",VLOOKUP($C23,성분!$B$2:$O$1509,8,FALSE))/100*$P23 -> 0 | K23: =IF($C23="","",VLOOKUP($C23,성분!$B$2:$O$1509,9,FALSE))/100*$P23 -> 0 | L23: =IF($C23="","",VLOOKUP($C23,성분!$B$2:$O$1509,10,FALSE))/100*$P23 -> 0 | M23: =IF($C23="","",VLOOKUP($C23,성분!$B$2:$O$1509,11,FALSE))/100*$P23 -> 0 | N23: =IF($C23="","",VLOOKUP($C23,성분!$B$2:$O$1509,12,FALSE))/100*$P23 -> 0 | O23: =IF($C23="","",VLOOKUP($C23,성분!$B$2:$O$1509,13,FALSE))/100*$P23 -> 0 | P23: =D23 -> 50 | Q23: =($O$8*P23)/1000 -> 8.2 | R23: =INT(Q23) -> 8
A24: =ROW()-10 -> 14 | C24: 옥수수볼 | D24: 40 | E24: 74.5 | F24: =IF($C24="","",VLOOKUP($C24,성분!$B$2:$O$10517,5,FALSE))/100*$P24 -> 22.8 | G24: 1 | H24: =IF($C24="","",VLOOKUP($C24,성분!$B$2:$O$10517,6,FALSE))/100*$P24 -> 2.4 | I24: =IF($C24="","",VLOOKUP($C24,성분!$B$2:$O$10517,7,FALSE))/100*$P24 -> 0 | J24: =IF($C24="","",VLOOKUP($C24,성분!$B$2:$O$10517,8,FALSE))/100*$P24 -> 0 | K24: =IF($C24="","",VLOOKUP($C24,성분!$B$2:$O$10517,9,FALSE))/100*$P24 -> 0 | L24: =IF($C24="","",VLOOKUP($C24,성분!$B$2:$O$10517,10,FALSE))/100*$P24 -> 0 | M24: =IF($C24="","",VLOOKUP($C24,성분!$B$2:$O$10517,11,FALSE))/100*$P24 -> 0 | N24: =IF($C24="","",VLOOKUP($C24,성분!$B$2:$O$10517,12,FALSE))/100*$P24 -> 0 | O24: =IF($C24="","",VLOOKUP($C24,성분!$B$2:$O$10517,13,FALSE))/100*$P24 -> 0 | P24: =D24 -> 40 | Q24: =($O$8*P24)/1000 -> 6.56 | R24: =INT(Q24) -> 6
A25: =ROW()-10 -> 15 | C25: 츄러스 | D25: 15 | E25: =IF($C25="","",VLOOKUP($C25,성분!$B$2:$O$10517,3,FALSE))/100*P25 -> 40.65 | F25: =IF($C25="","",VLOOKUP($C25,성분!$B$2:$O$10517,5,FALSE))/100*$P25 -> 8.7 | G25: 0.64 | H25: =IF($C25="","",VLOOKUP($C25,성분!$B$2:$O$10517,6,FALSE))/100*$P25 -> 1.665 | I25: 6.4 | J25: =IF($C25="","",VLOOKUP($C25,성분!$B$2:$O$10517,8,FALSE))/100*$P25 -> 0.105 | K25: =IF($C25="","",VLOOKUP($C25,성분!$B$2:$O$10517,9,FALSE))/100*$P25 -> 4.35 | L25: =IF($C25="","",VLOOKUP($C25,성분!$B$2:$O$10517,10,FALSE))/100*$P25 -> 0.021 | M25: =IF($C25="","",VLOOKUP($C25,성분!$B$2:$O$10517,11,FALSE))/100*$P25 -> 0.009 | N25: =IF($C25="","",VLOOKUP($C25,성분!$B$2:$O$10517,12,FALSE))/100*$P25 -> 0.195 | O25: =IF($C25="","",VLOOKUP($C25,성분!$B$2:$O$10517,13,FALSE))/100*$P25 -> 0 | P25: =D25 -> 15 | Q25: =($O$8*P25)/1000 -> 2.46 | R25: =INT(Q25) -> 2
A26: =ROW()-10 -> 16 | C26: 물엿 | D26: 1 | E26: =IF($C26="","",VLOOKUP($C26,성분!$B$2:$O$10517,3,FALSE))/100*P26 -> 2.93 | F26: =IF($C26="","",VLOOKUP($C26,성분!$B$2:$O$10517,5,FALSE))/100*$P26 -> 0.79 | G26: =IF($C26="","",VLOOKUP($C26,성분!$B$2:$O$10517,4,FALSE))/100*$P26 -> 0.001 | H26: =IF($C26="","",VLOOKUP($C26,성분!$B$2:$O$10517,6,FALSE))/100*$P26 -> 0 | I26: =IF($C26="","",VLOOKUP($C26,성분!$B$2:$O$10517,7,FALSE))/100*$P26 -> 0.01 | J26: =IF($C26="","",VLOOKUP($C26,성분!$B$2:$O$10517,8,FALSE))/100*$P26 -> 0.002 | K26: =IF($C26="","",VLOOKUP($C26,성분!$B$2:$O$10517,9,FALSE))/100*$P26 -> 0 | L26: =IF($C26="","",VLOOKUP($C26,성분!$B$2:$O$10517,10,FALSE))/100*$P26 -> 0 | M26: =IF($C26="","",VLOOKUP($C26,성분!$B$2:$O$10517,11,FALSE))/100*$P26 -> 0 | N26: =IF($C26="","",VLOOKUP($C26,성분!$B$2:$O$10517,12,FALSE))/100*$P26 -> 0 | O26: =IF($C26="","",VLOOKUP($C26,성분!$B$2:$O$10517,13,FALSE))/100*$P26 -> 0 | P26: =D26 -> 1 | Q26: =($O$8*P26)/1000 -> 0.164 | R26: =INT(Q26) -> 0
A27: =ROW()-10 -> 17 | B27: 단배추겉절이 | C27: 단배추 | D27: 25 | E27: =IF($C27="","",VLOOKUP($C27,성분!$B$2:$O$10517,3,FALSE))/100*P27 -> 2.5 | F27: =IF($C27="","",VLOOKUP($C27,성분!$B$2:$O$10517,5,FALSE))/100*$P27 -> 7.125 | G27: 0.24 | H27: =IF($C27="","",VLOOKUP($C27,성분!$B$2:$O$10517,6,FALSE))/100*$P27 -> 0.0225 | I27: 17.62 | J27: 0.45 | K27: =IF($C27="","",VLOOKUP($C27,성분!$B$2:$O$10517,9,FALSE))/100*$P27 -> 15.25 | L27: =IF($C27="","",VLOOKUP($C27,성분!$B$2:$O$10517,10,FALSE))/100*$P27 -> 0.0075 | M27: =IF($C27="","",VLOOKUP($C27,성분!$B$2:$O$10517,11,FALSE))/100*$P27 -> 0.0075 | N27: =IF($C27="","",VLOOKUP($C27,성분!$B$2:$O$10517,12,FALSE))/100*$P27 -> 0.175 | O27: =IF($C27="","",VLOOKUP($C27,성분!$B$2:$O$10517,13,FALSE))/100*$P27 -> 6 | P27: =D27 -> 25 | Q27: =($O$8*P27)/1000 -> 4.1 | R27: =INT(Q27) -> 4
A28: =ROW()-10 -> 18 | C28: 당근 | D28: 2 | E28: =IF($C28="","",VLOOKUP($C28,성분!$B$2:$O$10517,3,FALSE))/100*P28 -> 0.68 | F28: =IF($C28="","",VLOOKUP($C28,성분!$B$2:$O$10517,5,FALSE))/100*$P28 -> 0.1406 | G28: =IF($C28="","",VLOOKUP($C28,성분!$B$2:$O$10517,4,FALSE))/100*$P28 -> 0.02 | H28: =IF($C28="","",VLOOKUP($C28,성분!$B$2:$O$10517,6,FALSE))/100*$P28 -> 0.0026 | I28: =IF($C28="","",VLOOKUP($C28,성분!$B$2:$O$10517,7,FALSE))/100*$P28 -> 0.76 | J28: =IF($C28="","",VLOOKUP($C28,성분!$B$2:$O$10517,8,FALSE))/100*$P28 -> 0.014 | K28: =IF($C28="","",VLOOKUP($C28,성분!$B$2:$O$10517,9,FALSE))/100*$P28 -> 25.14 | L28: =IF($C28="","",VLOOKUP($C28,성분!$B$2:$O$10517,10,FALSE))/100*$P28 -> 0.0012 | M28: =IF($C28="","",VLOOKUP($C28,성분!$B$2:$O$10517,11,FALSE))/100*$P28 -> 0.0008 | N28: =IF($C28="","",VLOOKUP($C28,성분!$B$2:$O$10517,12,FALSE))/100*$P28 -> 0.016 | O28: =IF($C28="","",VLOOKUP($C28,성분!$B$2:$O$10517,13,FALSE))/100*$P28 -> 0.12 | P28: =D28 -> 2 | Q28: =($O$8*P28)/1000 -> 0.328 | R28: =INT(Q28) -> 0
A29: =ROW()-10 -> 19 | C29: 참기름 | D29: 1 | E29: =IF($C29="","",VLOOKUP($C29,성분!$B$2:$O$10517,3,FALSE))/100*P29 -> 8.84 | F29: =IF($C29="","",VLOOKUP($C29,성분!$B$2:$O$10517,5,FALSE))/100*$P29 -> 0.004 | G29: =IF($C29="","",VLOOKUP($C29,성분!$B$2:$O$10517,4,FALSE))/100*$P29 -> 0 | H29: =IF($C29="","",VLOOKUP($C29,성분!$B$2:$O$10517,6,FALSE))/100*$P29 -> 1 | I29: =IF($C29="","",VLOOKUP($C29,성분!$B$2:$O$10517,7,FALSE))/100*$P29 -> 0 | J29: =IF($C29="","",VLOOKUP($C29,성분!$B$2:$O$10517,8,FALSE))/100*$P29 -> 0 | K29: =IF($C29="","",VLOOKUP($C29,성분!$B$2:$O$10517,9,FALSE))/100*$P29 -> 0 | L29: =IF($C29="","",VLOOKUP($C29,성분!$B$2:$O$10517,10,FALSE))/100*$P29 -> 0 | M29: =IF($C29="","",VLOOKUP($C29,성분!$B$2:$O$10517,11,FALSE))/100*$P29 -> 0 | N29: =IF($C29="","",VLOOKUP($C29,성분!$B$2:$O$10517,12,FALSE))/100*$P29 -> 0 | O29: =IF($C29="","",VLOOKUP($C29,성분!$B$2:$O$10517,13,FALSE))/100*$P29 -> 0 | P29: =D29 -> 1 | Q29: =($O$8*P29)/1000 -> 0.164 | R29: =INT(Q29) -> 0
A30: =ROW()-10 -> 20 | B30: 딸기타임 | C30: 딸기타임 | D30: 100 | E30: =IF($C30="","",VLOOKUP($C30,성분!$B$2:$O$10517,3,FALSE))/100*P30 -> 57.5 | F30: =IF($C30="","",VLOOKUP($C30,성분!$B$2:$O$10517,5,FALSE))/100*$P30 -> 10.5 | G30: 1.4 | H30: =IF($C30="","",VLOOKUP($C30,성분!$B$2:$O$10517,6,FALSE))/100*$P30 -> 1 | I30: =IF($C30="","",VLOOKUP($C30,성분!$B$2:$O$10517,7,FALSE))/100*$P30 -> 0 | J30: =IF($C30="","",VLOOKUP($C30,성분!$B$2:$O$10517,8,FALSE))/100*$P30 -> 0 | K30: =IF($C30="","",VLOOKUP($C30,성분!$B$2:$O$10517,9,FALSE))/100*$P30 -> 0 | L30: =IF($C30="","",VLOOKUP($C30,성분!$B$2:$O$10517,10,FALSE))/100*$P30 -> 0 | M30: =IF($C30="","",VLOOKUP($C30,성분!$B$2:$O$10517,11,FALSE))/100*$P30 -> 0 | N30: =IF($C30="","",VLOOKUP($C30,성분!$B$2:$O$10517,12,FALSE))/100*$P30 -> 0 | O30: =IF($C30="","",VLOOKUP($C30,성분!$B$2:$O$10517,13,FALSE))/100*$P30 -> 0 | P30: =D30 -> 100 | Q30: =($O$8*P30)/1000 -> 16.4 | R30: =INT(Q30) -> 16
A31: 1인 기준량 | E31: =SUM(E11:E30) -> 695 | F31: =SUM(F11:F30) -> 147.7274 | G31: =SUM(G11:G30) -> 29.495 | H31: =SUM(H11:H30) -> 31.4761 | I31: =SUM(I11:I30) -> 236.08 | J31: =SUM(J11:J30) -> 3.184 | K31: =SUM(K11:K30) -> 131.17 | L31: =SUM(L11:L30) -> 0.2191 | ... O31: =SUM(O11:O30) -> 15.72 | P31: =D31 -> 0 | Q31: =($O$8*P31)/1000 -> 0 | R31: =INT(Q31) -> 0
A32: 급식모니터링, 대면검수 1. 맛 양호 2. 이물,이취 등 없음 3.조리상태 양호. | R32: =INT(Q32) -> 0
A33: ※식품원산지표기 | S33: =INT(R33) -> 0
A34: 쌀: 국내산 | P34: 1인 급식비 | R34: 5000
A35: 포기김치:배추(국내산) / 돼지고기(국내산) / 닭고기(국내산) / 식육가공품(국내산/외국산) | P35: 1인 식품비 | R35: =R34*0.72 -> 3600
P36: 비율 | R36: 0.72
G37: 667 | H37: 15 | I37: 300 | J37: 5.4 | K37: 234 | L37: 0.34 | M37: 0.4 | N37: 5.26 | O37: 33.4
D1347: 240

Sheet 1화
M1: 업체담당 | N1: 학교담당 | O1: 행정실장
M2: 정소예
A3: 일 자 : | C3: 45748 | E3: 석식
A6: 급식학생수 | O6: 총계
A7: 구분 | D7: 1학년 | F7: 2학년 | H7: 3학년 | K7: 합계 | M7: 교직원
A8: 심인고등학교 | D8: 0 | F8: 0 | H8: 104 | K8: =SUM(D8:J8) -> 104 | M8: 2 | O8: =SUM(K8:N8) -> 106
A9: 식 단 | D9: 백미밥,크림스프,치킨스테이크,미트소스스파게티,김치볶음,부시맨빵&초코잼
A10: 번호 | B10: 메뉴명 | C10: 식품명 | D10: 1인량 (g) | E10: 열량 (kcal) | F10: 탄수화물 (g) | G10: 단백질 (g) | H10: 지방 (g) | I10: 칼슘 (mg) | J10: 철 (mg) | K10: VIT-A (RE) | L10: VIT-B1 (mg) | M10: VIT-B2 (mg) | N10: NIACIN (mg) | O10: VIT-C | P10: 기준량 | Q10: 총량
A11: =ROW()-10 -> 1 | B11: 백미밥 | C11: 쌀 | D11: 100 | E11: =IF($C11="","",VLOOKUP($C11,성분!$B$2:$O$1509,3,FALSE))/100*P11 -> 240 | F11: =IF($C11="","",VLOOKUP($C11,성분!$B$2:$O$1509,5,FALSE))/100*$P11 -> 78.5 | G11: =IF($C11="","",VLOOKUP($C11,성분!$B$2:$O$1509,4,FALSE))/100*$P11 -> 6.4 | H11: =IF($C11="","",VLOOKUP($C11,성분!$B$2:$O$1509,6,FALSE))/100*$P11 -> 0.4 | I11: =IF($C11="","",VLOOKUP($C11,성분!$B$2:$O$1509,7,FALSE))/100*$P11 -> 7 | J11: =IF($C11="","",VLOOKUP($C11,성분!$B$2:$O$1509,8,FALSE))/100*$P11 -> 0.5 | K11: =IF($C11="","",VLOOKUP($C11,성분!$B$2:$O$1509,9,FALSE))/100*$P11 -> 0 | L11: =IF($C11="","",VLOOKUP($C11,성분!$B$2:$O$1509,10,FALSE))/100*$P11 -> 0.12 | M11: =IF($C11="","",VLOOKUP($C11,성분!$B$2:$O$1509,11,FALSE))/100*$P11 -> 0 | N11: =IF($C11="","",VLOOKUP($C11,성분!$B$2:$O$1509,12,FALSE))/100*$P11 -> 1.4 | O11: =IF($C11="","",VLOOKUP($C11,성분!$B$2:$O$1509,13,FALSE))/100*$P11 -> 0 | P11: =D11 -> 100 | Q11: =($O$8*P11)/1000 -> 10.6 | R11: =INT(Q11) -> 10
A12: =ROW()-10 -> 2 | B12: 크림스프 | C12: 크림스프 | D12: 20 | E12: =IF($C12="","",VLOOKUP($C12,성분!$B$2:$O$1509,3,FALSE))/100*P12 -> 90.8 | F12: =IF($C12="","",VLOOKUP($C12,성분!$B$2:$O$1509,5,FALSE))/100*$P12 -> 12.8 | G12: =IF($C12="","",VLOOKUP($C12,성분!$B$2:$O$1509,4,FALSE))/100*$P12 -> 1.46 | H12: =IF($C12="","",VLOOKUP($C12,성분!$B$2:$O$1509,6,FALSE))/100*$P12 -> 3.74 | I12: =IF($C12="","",VLOOKUP($C12,성분!$B$2:$O$1509,7,FALSE))/100*$P12 -> 17.8 | J12: =IF($C12="","",VLOOKUP($C12,성분!$B$2:$O$1509,8,FALSE))/100*$P12 -> 0.1 | K12: =IF($C12="","",VLOOKUP($C12,성분!$B$2:$O$1509,9,FALSE))/100*$P12 -> 15.2 | L12: =IF($C12="","",VLOOKUP($C12,성분!$B$2:$O$1509,10,FALSE))/100*$P12 -> 0.918 | M12: =IF($C12="","",VLOOKUP($C12,성분!$B$2:$O$1509,11,FALSE))/100*$P12 -> 0.01 | N12: =IF($C12="","",VLOOKUP($C12,성분!$B$2:$O$1509,12,FALSE))/100*$P12 -> 0.26 | O12: =IF($C12="","",VLOOKUP($C12,성분!$B$2:$O$1509,13,FALSE))/100*$P12 -> 0 | P12: =D12 -> 20 | Q12: =($O$8*P12)/1000 -> 2.12 | R12: =INT(Q12) -> 2
A13: =ROW()-10 -> 3 | C13: 당근 | D13: 3 | E13: =IF($C13="","",VLOOKUP($C13,성분!$B$2:$O$1509,3,FALSE))/100*P13 -> 1.02 | F13: =IF($C13="","",VLOOKUP($C13,성분!$B$2:$O$1509,5,FALSE))/100*$P13 -> 0.2109 | G13: =IF($C13="","",VLOOKUP($C13,성분!$B$2:$O$1509,4,FALSE))/100*$P13 -> 0.03 | H13: =IF($C13="","",VLOOKUP($C13,성분!$B$2:$O$1509,6,FALSE))/100*$P13 -> 0.0039 | I13: =IF($C13="","",VLOOKUP($C13,성분!$B$2:$O$1509,7,FALSE))/100*$P13 -> 1.14 | J13: =IF($C13="","",VLOOKUP($C13,성분!$B$2:$O$1509,8,FALSE))/100*$P13 -> 0.021 | K13: =IF($C13="","",VLOOKUP($C13,성분!$B$2:$O$1509,9,FALSE))/100*$P13 -> 37.71 | L13: =IF($C13="","",VLOOKUP($C13,성분!$B$2:$O$1509,10,FALSE))/100*$P13 -> 0.0018 | M13: =IF($C13="","",VLOOKUP($C13,성분!$B$2:$O$1509,11,FALSE))/100*$P13 -> 0.0012 | N13: =IF($C13="","",VLOOKUP($C13,성분!$B$2:$O$1509,12,FALSE))/100*$P13 -> 0.024 | O13: =IF($C13="","",VLOOKUP($C13,성분!$B$2:$O$1509,13,FALSE))/100*$P13 -> 0.18 | P13: =D13 -> 3 | Q13: =($O$8*P13)/1000 -> 0.318 | R13: =INT(Q13) -> 0
A14: =ROW()-10 -> 4 | C14: 파슬리찹 | D14: 1 | E14: =IF($C14="","",VLOOKUP($C14,성분!$B$2:$O$1509,3,FALSE))/100*P14 -> 2.92 | F14: =IF($C14="","",VLOOKUP($C14,성분!$B$2:$O$1509,5,FALSE))/100*$P14 -> 0.5064 | G14: =IF($C14="","",VLOOKUP($C14,성분!$B$2:$O$1509,4,FALSE))/100*$P14 -> 0.2663 | H14: =IF($C14="","",VLOOKUP($C14,성분!$B$2:$O$1509,6,FALSE))/100*$P14 -> 0.0548 | I14: =IF($C14="","",VLOOKUP($C14,성분!$B$2:$O$1509,7,FALSE))/100*$P14 -> 11.4 | J14: =IF($C14="","",VLOOKUP($C14,성분!$B$2:$O$1509,8,FALSE))/100*$P14 -> 0.2204 | K14: =IF($C14="","",VLOOKUP($C14,성분!$B$2:$O$1509,9,FALSE))/100*$P14 -> 11.52 | L14: =IF($C14="","",VLOOKUP($C14,성분!$B$2:$O$1509,10,FALSE))/100*$P14 -> 0.002 | M14: =IF($C14="","",VLOOKUP($C14,성분!$B$2:$O$1509,11,FALSE))/100*$P14 -> 0.0238 | N14: =IF($C14="","",VLOOKUP($C14,성분!$B$2:$O$1509,12,FALSE))/100*$P14 -> 0.0994 | O14: =IF($C14="","",VLOOKUP($C14,성분!$B$2:$O$1509,13,FALSE))/100*$P14 -> 1.25 | P14: =D14 -> 1 | Q14: =($O$8*P14)/1000 -> 0.106 | R14: =INT(Q14) -> 0
A15: =ROW()-10 -> 5 | B15: 치킨스테이크 | C15: 치킨스테이크 | D15: 100 | E15: =IF($C15="","",VLOOKUP($C15,성분!$B$2:$O$1509,3,FALSE))/100*P15 -> 200 | F15: =IF($C15="","",VLOOKUP($C15,성분!$B$2:$O$1509,5,FALSE))/100*$P15 -> 10 | G15: =IF($C15="","",VLOOKUP($C15,성분!$B$2:$O$1509,4,FALSE))/100*$P15 -> 15 | H15: =IF($C15="","",VLOOKUP($C15,성분!$B$2:$O$1509,6,FALSE))/100*$P15 -> 11 | I15: =IF($C15="","",VLOOKUP($C15,성분!$B$2:$O$1509,7,FALSE))/100*$P15 -> 0 | J15: =IF($C15="","",VLOOKUP($C15,성분!$B$2:$O$1509,8,FALSE))/100*$P15 -> 0 | K15: =IF($C15="","",VLOOKUP($C15,성분!$B$2:$O$1509,9,FALSE))/100*$P15 -> 0 | L15: =IF($C15="","",VLOOKUP($C15,성분!$B$2:$O$1509,10,FALSE))/100*$P15 -> 0 | M15: =IF($C15="","",VLOOKUP($C15,성분!$B$2:$O$1509,11,FALSE))/100*$P15 -> 0 | N15: =IF($C15="","",VLOOKUP($C15,성분!$B$2:$O$1509,12,FALSE))/100*$P15 -> 0 | O15: =IF($C15="","",VLOOKUP($C15,성분!$B$2:$O$1509,13,FALSE))/100*$P15 -> 0 | P15: =D15 -> 100 | Q15: =($O$8*P15)/1000 -> 10.6 | R15: =INT(Q15) -> 10
A16: =ROW()-10 -> 6 | C16: 스테이크소스 | D16: 15 | E16: =IF($C16="","",VLOOKUP($C16,성분!$B$2:$O$1509,3,FALSE))/100*P16 -> 17.85 | F16: =IF($C16="","",VLOOKUP($C16,성분!$B$2:$O$1509,5,FALSE))/100*$P16 -> 4.275 | G16: =IF($C16="","",VLOOKUP($C16,성분!$B$2:$O$1509,4,FALSE))/100*$P16 -> 0.165 | H16: =IF($C16="","",VLOOKUP($C16,성분!$B$2:$O$1509,6,FALSE))/100*$P16 -> 0.96 | I16: =IF($C16="","",VLOOKUP($C16,성분!$B$2:$O$1509,7,FALSE))/100*$P16 -> 0 | J16: =IF($C16="","",VLOOKUP($C16,성분!$B$2:$O$1509,8,FALSE))/100*$P16 -> 0 | K16: =IF($C16="","",VLOOKUP($C16,성분!$B$2:$O$1509,9,FALSE))/100*$P16 -> 0 | L16: =IF($C16="","",VLOOKUP($C16,성분!$B$2:$O$1509,10,FALSE))/100*$P16 -> 0 | M16: =IF($C16="","",VLOOKUP($C16,성분!$B$2:$O$1509,11,FALSE))/100*$P16 -> 0 | N16: =IF($C16="","",VLOOKUP($C16,성분!$B$2:$O$1509,12,FALSE))/100*$P16 -> 0 | O16: =IF($C16="","",VLOOKUP($C16,성분!$B$2:$O$1509,13,FALSE))/100*$P16 -> 0 | P16: =D16 -> 15 | Q16: =($O$8*P16)/1000 -> 1.59 | R16: =INT(Q16) -> 1
A17: =ROW()-10 -> 7 | C17: 양파 | D17: 15 | E17: =IF($C17="","",VLOOKUP($C17,성분!$B$2:$O$1509,3,FALSE))/100*P17 -> 5.25 | F17: =IF($C17="","",VLOOKUP($C17,성분!$B$2:$O$1509,5,FALSE))/100*$P17 -> 1.149 | G17: =IF($C17="","",VLOOKUP($C17,성분!$B$2:$O$1509,4,FALSE))/100*$P17 -> 0.15 | H17: =IF($C17="","",VLOOKUP($C17,성분!$B$2:$O$1509,6,FALSE))/100*$P17 -> 0.0285 | I17: =IF($C17="","",VLOOKUP($C17,성분!$B$2:$O$1509,7,FALSE))/100*$P17 -> 2.25 | J17: =IF($C17="","",VLOOKUP($C17,성분!$B$2:$O$1509,8,FALSE))/100*$P17 -> 0.045 | K17: =IF($C17="","",VLOOKUP($C17,성분!$B$2:$O$1509,9,FALSE))/100*$P17 -> 0 | L17: =IF($C17="","",VLOOKUP($C17,성분!$B$2:$O$1509,10,FALSE))/100*$P17 -> 0.006 | M17: =IF($C17="","",VLOOKUP($C17,성분!$B$2:$O$1509,11,FALSE))/100*$P17 -> 0.0015 | N17: =IF($C17="","",VLOOKUP($C17,성분!$B$2:$O$1509,12,FALSE))/100*$P17 -> 0.03 | O17: =IF($C17="","",VLOOKUP($C17,성분!$B$2:$O$1509,13,FALSE))/100*$P17 -> 1.2 | P17: =D17 -> 15 | Q17: =($O$8*P17)/1000 -> 1.59 | R17: =INT(Q17) -> 1
A18: =ROW()-10 -> 8 | C18: 양송이버섯캔 | D18: 10 | E18: =IF($C18="","",VLOOKUP($C18,성분!$B$2:$O$1509,3,FALSE))/100*P18 -> 13.2 | F18: =IF($C18="","",VLOOKUP($C18,성분!$B$2:$O$1509,5,FALSE))/100*$P18 -> 0.387 | G18: =IF($C18="","",VLOOKUP($C18,성분!$B$2:$O$1509,4,FALSE))/100*$P18 -> 0.375 | H18: =IF($C18="","",VLOOKUP($C18,성분!$B$2:$O$1509,6,FALSE))/100*$P18 -> 0.041 | I18: =IF($C18="","",VLOOKUP($C18,성분!$B$2:$O$1509,7,FALSE))/100*$P18 -> 0.6 | J18: =IF($C18="","",VLOOKUP($C18,성분!$B$2:$O$1509,8,FALSE))/100*$P18 -> 0.063 | K18: =IF($C18="","",VLOOKUP($C18,성분!$B$2:$O$1509,9,FALSE))/100*$P18 -> 0.2 | L18: =IF($C18="","",VLOOKUP($C18,성분!$B$2:$O$1509,10,FALSE))/100*$P18 -> 0 | M18: =IF($C18="","",VLOOKUP($C18,성분!$B$2:$O$1509,11,FALSE))/100*$P18 -> 0.005 | N18: =IF($C18="","",VLOOKUP($C18,성분!$B$2:$O$1509,12,FALSE))/100*$P18 -> 0.075 | O18: =IF($C18="","",VLOOKUP($C18,성분!$B$2:$O$1509,13,FALSE))/100*$P18 -> 0.288 | P18: =D18 -> 10 | Q18: =($O$8*P18)/1000 -> 1.06 | R18: =INT(Q18) -> 1
A19: =ROW()-10 -> 9 | B19: 미트소스스파게티 | C19: 스파게티면 | D19: 38 | E19: =IF($C19="","",VLOOKUP($C19,성분!$B$2:$O$1509,3,FALSE))/100*P19 -> 135.66 | F19: =IF($C19="","",VLOOKUP($C19,성분!$B$2:$O$1509,5,FALSE))/100*$P19 -> 28.348 | G19: =IF($C19="","",VLOOKUP($C19,성분!$B$2:$O$1509,4,FALSE))/100*$P19 -> 4.256 | H19: =IF($C19="","",VLOOKUP($C19,성분!$B$2:$O$1509,6,FALSE))/100*$P19 -> 0.76 | I19: =IF($C19="","",VLOOKUP($C19,성분!$B$2:$O$1509,7,FALSE))/100*$P19 -> 9.88 | J19: =IF($C19="","",VLOOKUP($C19,성분!$B$2:$O$1509,8,FALSE))/100*$P19 -> 0.57 | K19: =IF($C19="","",VLOOKUP($C19,성분!$B$2:$O$1509,9,FALSE))/100*$P19 -> 0 | L19: =IF($C19="","",VLOOKUP($C19,성분!$B$2:$O$1509,10,FALSE))/100*$P19 -> 0 | M19: =IF($C19="","",VLOOKUP($C19,성분!$B$2:$O$1509,11,FALSE))/100*$P19 -> 0 | N19: =IF($C19="","",VLOOKUP($C19,성분!$B$2:$O$1509,12,FALSE))/100*$P19 -> 0 | O19: =IF($C19="","",VLOOKUP($C19,성분!$B$2:$O$1509,13,FALSE))/100*$P19 -> 0 | P19: =D19 -> 38 | Q19: =($O$8*P19)/1000 -> 4.028 | R19: =INT(Q19) -> 4
A20: =ROW()-10 -> 10 | C20: 돈민찌 | D20: 7 | E20: =IF($C20="","",VLOOKUP($C20,성분!$B$2:$O$1509,3,FALSE))/100*P20 -> 8.47 | F20: =IF($C20="","",VLOOKUP($C20,성분!$B$2:$O$1509,5,FALSE))/100*$P20 -> 0 | G20: =IF($C20="","",VLOOKUP($C20,성분!$B$2:$O$1509,4,FALSE))/100*$P20 -> 0.987 | H20: =IF($C20="","",VLOOKUP($C20,성분!$B$2:$O$1509,6,FALSE))/100*$P20 -> 1.155 | I20: =IF($C20="","",VLOOKUP($C20,성분!$B$2:$O$1509,7,FALSE))/100*$P20 -> 0.14 | J20: =IF($C20="","",VLOOKUP($C20,성분!$B$2:$O$1509,8,FALSE))/100*$P20 -> 0.112 | K20: =IF($C20="","",VLOOKUP($C20,성분!$B$2:$O$1509,9,FALSE))/100*$P20 -> 0.14 | L20: =IF($C20="","",VLOOKUP($C20,성분!$B$2:$O$1509,10,FALSE))/100*$P20 -> 0.0637 | M20: =IF($C20="","",VLOOKUP($C20,성분!$B$2:$O$1509,11,FALSE))/100*$P20 -> 0.0126 | N20: =IF($C20="","",VLOOKUP($C20,성분!$B$2:$O$1509,12,FALSE))/100*$P20 -> 0.287 | O20: =IF($C20="","",VLOOKUP($C20,성분!$B$2:$O$1509,13,FALSE))/100*$P20 -> 0 | P20: =D20 -> 7 | Q20: =($O$8*P20)/1000 -> 0.742 | R20: =INT(Q20) -> 0
A21: =ROW()-10 -> 11 | C21: 베이컨 | D21: 7 | E21: =IF($C21="","",VLOOKUP($C21,성분!$B$2:$O$1509,3,FALSE))/100*P21 -> 21.56 | F21: =IF($C21="","",VLOOKUP($C21,성분!$B$2:$O$10517,5,FALSE))/100*$P21 -> 0.098 | G21: =IF($C21="","",VLOOKUP($C21,성분!$B$2:$O$1509,4,FALSE))/100*$P21 -> 1.197 | H21: =IF($C21="","",VLOOKUP($C21,성분!$B$2:$O$1509,6,FALSE))/100*$P21 -> 0.945 | I21: =IF($C21="","",VLOOKUP($C21,성분!$B$2:$O$1509,7,FALSE))/100*$P21 -> 0.7 | J21: =IF($C21="","",VLOOKUP($C21,성분!$B$2:$O$1509,8,FALSE))/100*$P21 -> 0.056 | K21: =IF($C21="","",VLOOKUP($C21,성분!$B$2:$O$1509,9,FALSE))/100*$P21 -> 0.56 | L21: =IF($C21="","",VLOOKUP($C21,성분!$B$2:$O$1509,10,FALSE))/100*$P21 -> 0.035 | M21: =IF($C21="","",VLOOKUP($C21,성분!$B$2:$O$10517,11,FALSE))/100*$P21 -> 0.007 | N21: =IF($C21="","",VLOOKUP($C21,성분!$B$2:$O$10517,12,FALSE))/100*$P21 -> 0.329 | O21: =IF($C21="","",VLOOKUP($C21,성분!$B$2:$O$10517,13,FALSE))/100*$P21 -> 1.89 | P21: =D21 -> 7 | Q21: =($O$8*P21)/1000 -> 0.742 | R21: =INT(Q21) -> 0
A22: =ROW()-10 -> 12 | C22: 청피망 | D22: 7 | E22: =IF($C22="","",VLOOKUP($C22,성분!$B$2:$O$10517,3,FALSE))/100*P22 -> 1.19 | F22: =IF($C22="","",VLOOKUP($C22,성분!$B$2:$O$10517,5,FALSE))/100*$P22 -> 0.2226 | G22: =IF($C22="","",VLOOKUP($C22,성분!$B$2:$O$1509,4,FALSE))/100*$P22 -> 0 | H22: =IF($C22="","",VLOOKUP($C22,성분!$B$2:$O$1509,6,FALSE))/100*$P22 -> 0.0098 | I22: =IF($C22="","",VLOOKUP($C22,성분!$B$2:$O$1509,7,FALSE))/100*$P22 -> 0.7 | J22: =IF($C22="","",VLOOKUP($C22,성분!$B$2:$O$1509,8,FALSE))/100*$P22 -> 0.035 | K22: =IF($C22="","",VLOOKUP($C22,성분!$B$2:$O$1509,9,FALSE))/100*$P22 -> 4.48 | L22: =IF($C22="","",VLOOKUP($C22,성분!$B$2:$O$1509,10,FALSE))/100*$P22 -> 0.0021 | M22: =IF($C22="","",VLOOKUP($C22,성분!$B$2:$O$10517,11,FALSE))/100*$P22 -> 0.0049 | N22: =IF($C22="","",VLOOKUP($C22,성분!$B$2:$O$10517,12,FALSE))/100*$P22 -> 0.049 | O22: =IF($C22="","",VLOOKUP($C22,성분!$B$2:$O$10517,13,FALSE))/100*$P22 -> 3.71 | P22: =D22 -> 7 | Q22: =($O$8*P22)/1000 -> 0.742 | R22: =INT(Q22) -> 0
A23: =ROW()-10 -> 13 | C23: 양파 | D23: 10 | E23: =IF($C23="","",VLOOKUP($C23,성분!$B$2:$O$10517,3,FALSE))/100*P23 -> 3.5 | F23: =IF($C23="","",VLOOKUP($C23,성분!$B$2:$O$10517,5,FALSE))/100*$P23 -> 0.766 | G23: =IF($C23="","",VLOOKUP($C23,성분!$B$2:$O$1509,4,FALSE))/100*$P23 -> 0.1 | H23: =IF($C23="","",VLOOKUP($C23,성분!$B$2:$O$1509,6,FALSE))/100*$P23 -> 0.019 | I23: =IF($C23="","",VLOOKUP($C23,성분!$B$2:$O$1509,7,FALSE))/100*$P23 -> 1.5 | J23: =IF($C23="","",VLOOKUP($C23,성분!$B$2:$O$1509,8,FALSE))/100*$P23 -> 0.03 | K23: =IF($C23="","",VLOOKUP($C23,성분!$B$2:$O$1509,9,FALSE))/100*$P23 -> 0 | L23: =IF($C23="","",VLOOKUP($C23,성분!$B$2:$O$1509,10,FALSE))/100*$P23 -> 0.004 | M23: =IF($C23="","",VLOOKUP($C23,성분!$B$2:$O$10517,11,FALSE))/100*$P23 -> 0.001 | N23: =IF($C23="","",VLOOKUP($C23,성분!$B$2:$O$10517,12,FALSE))/100*$P23 -> 0.02 | O23: =IF($C23="","",VLOOKUP($C23,성분!$B$2:$O$10517,13,FALSE))/100*$P23 -> 0.8 | P23: =D23 -> 10 | Q23: =($O$8*P23)/1000 -> 1.06 | R23: =INT(Q23) -> 1
A24: =ROW()-10 -> 14 | C24: 양송이버섯캔 | D24: 10 | E24: =IF($C24="","",VLOOKUP($C24,성분!$B$2:$O$10517,3,FALSE))/100*P24 -> 13.2 | F24: =IF($C24="","",VLOOKUP($C24,성분!$B$2:$O$10517,5,FALSE))/100*$P24 -> 0.387 | G24: =IF($C24="","",VLOOKUP($C24,성분!$B$2:$O$1509,4,FALSE))/100*$P24 -> 0.375 | H24: =IF($C24="","",VLOOKUP($C24,성분!$B$2:$O$1509,6,FALSE))/100*$P24 -> 0.041 | I24: =IF($C24="","",VLOOKUP($C24,성분!$B$2:$O$1509,7,FALSE))/100*$P24 -> 0.6 | J24: =IF($C24="","",VLOOKUP($C24,성분!$B$2:$O$1509,8,FALSE))/100*$P24 -> 0.063 | K24: =IF($C24="","",VLOOKUP($C24,성분!$B$2:$O$1509,9,FALSE))/100*$P24 -> 0.2 | L24: =IF($C24="","",VLOOKUP($C24,성분!$B$2:$O$1509,10,FALSE))/100*$P24 -> 0 | M24: =IF($C24="","",VLOOKUP($C24,성분!$B$2:$O$10517,11,FALSE))/100*$P24 -> 0.005 | N24: =IF($C24="","",VLOOKUP($C24,성분!$B$2:$O$10517,12,FALSE))/100*$P24 -> 0.075 | O24: =IF($C24="","",VLOOKUP($C24,성분!$B$2:$O$10517,13,FALSE))/100*$P24 -> 0.288 | P24: =D24 -> 10 | Q24: =($O$8*P24)/1000 -> 1.06 | R24: =INT(Q24) -> 1
A25: =ROW()-10 -> 15 | C25: 토마토페이스트 | D25: 10 | E25: =IF($C25="","",VLOOKUP($C25,성분!$B$2:$O$10517,3,FALSE))/100*P25 -> 8.7 | F25: =IF($C25="","",VLOOKUP($C25,성분!$B$2:$O$10517,5,FALSE))/100*$P25 -> 1.98 | G25: =IF($C25="","",VLOOKUP($C25,성분!$B$2:$O$1509,4,FALSE))/100*$P25 -> 0.37 | H25: =IF($C25="","",VLOOKUP($C25,성분!$B$2:$O$1509,6,FALSE))/100*$P25 -> 0.024 | I25: =IF($C25="","",VLOOKUP($C25,성분!$B$2:$O$1509,7,FALSE))/100*$P25 -> 4.5 | J25: =IF($C25="","",VLOOKUP($C25,성분!$B$2:$O$1509,8,FALSE))/100*$P25 -> 0.15 | K25: =IF($C25="","",VLOOKUP($C25,성분!$B$2:$O$1509,9,FALSE))/100*$P25 -> 33.3 | L25: =IF($C25="","",VLOOKUP($C25,성분!$B$2:$O$1509,10,FALSE))/100*$P25 -> 0.02 | M25: =IF($C25="","",VLOOKUP($C25,성분!$B$2:$O$10517,11,FALSE))/100*$P25 -> 0.014 | N25: =IF($C25="","",VLOOKUP($C25,성분!$B$2:$O$10517,12,FALSE))/100*$P25 -> 0.36 | O25: =IF($C25="","",VLOOKUP($C25,성분!$B$2:$O$10517,13,FALSE))/100*$P25 -> 5.5 | P25: =D25 -> 10 | Q25: =($O$8*P25)/1000 -> 1.06 | R25: =INT(Q25) -> 1
A26: =ROW()-10 -> 16 | B26: 김치볶음 | C26: 맛김치 | D26: 60 | E26: =IF($C26="","",VLOOKUP($C26,성분!$B$2:$O$10517,3,FALSE))/100*P26 -> 30 | F26: =IF($C26="","",VLOOKUP($C26,성분!$B$2:$O$10517,5,FALSE))/100*$P26 -> 2.64 | G26: =IF($C26="","",VLOOKUP($C26,성분!$B$2:$O$1509,4,FALSE))/100*$P26 -> 1.2 | H26: =IF($C26="","",VLOOKUP($C26,성분!$B$2:$O$1509,6,FALSE))/100*$P26 -> 0.12 | I26: =IF($C26="","",VLOOKUP($C26,성분!$B$2:$O$1509,7,FALSE))/100*$P26 -> 28.2 | J26: =IF($C26="","",VLOOKUP($C26,성분!$B$2:$O$1509,8,FALSE))/100*$P26 -> 0.48 | K26: =IF($C26="","",VLOOKUP($C26,성분!$B$2:$O$1509,9,FALSE))/100*$P26 -> 28.8 | L26: =IF($C26="","",VLOOKUP($C26,성분!$B$2:$O$1509,10,FALSE))/100*$P26 -> 0.036 | M26: =IF($C26="","",VLOOKUP($C26,성분!$B$2:$O$10517,11,FALSE))/100*$P26 -> 0.036 | N26: =IF($C26="","",VLOOKUP($C26,성분!$B$2:$O$10517,12,FALSE))/100*$P26 -> 0.48 | O26: =IF($C26="","",VLOOKUP($C26,성분!$B$2:$O$10517,13,FALSE))/100*$P26 -> 8.4 | P26: =D26 -> 60 | Q26: =($O$8*P26)/1000 -> 6.36 | R26: =INT(Q26) -> 6
A27: =ROW()-10 -> 17 | B27: 부시맨빵&초코쨈 | C27: 부시맨빵 | D27: 35 | E27: =IF($C27="","",VLOOKUP($C27,성분!$B$2:$O$10517,3,FALSE))/100*P27 -> 32.55 | F27: =IF($C27="","",VLOOKUP($C27,성분!$B$2:$O$10517,5,FALSE))/100*$P27 -> 6.65 | G27: =IF($C27="","",VLOOKUP($C27,성분!$B$2:$O$1509,4,FALSE))/100*$P27 -> 0.35 | H27: =IF($C27="","",VLOOKUP($C27,성분!$B$2:$O$1509,6,FALSE))/100*$P27 -> 0 | I27: =IF($C27="","",VLOOKUP($C27,성분!$B$2:$O$1509,7,FALSE))/100*$P27 -> 0 | J27: =IF($C27="","",VLOOKUP($C27,성분!$B$2:$O$1509,8,FALSE))/100*$P27 -> 0 | K27: =IF($C27="","",VLOOKUP($C27,성분!$B$2:$O$1509,9,FALSE))/100*$P27 -> 0 | L27: =IF($C27="","",VLOOKUP($C27,성분!$B$2:$O$1509,10,FALSE))/100*$P27 -> 0 | M27: =IF($C27="","",VLOOKUP($C27,성분!$B$2:$O$10517,11,FALSE))/100*$P27 -> 0 | N27: =IF($C27="","",VLOOKUP($C27,성분!$B$2:$O$10517,12,FALSE))/100*$P27 -> 0 | O27: =IF($C27="","",VLOOKUP($C27,성분!$B$2:$O$10517,13,FALSE))/100*$P27 -> 0 | P27: =D27 -> 35 | Q27: =($O$8*P27)/1000 -> 3.71 | R27: =INT(Q27) -> 3
A28: =ROW()-10 -> 18 | C28: 초코잼 | D28: 12 | E28: =IF($C28="","",VLOOKUP($C28,성분!$B$2:$O$10517,3,FALSE))/100*P28 -> 49.92 | F28: =IF($C28="","",VLOOKUP($C28,성분!$B$2:$O$10517,5,FALSE))/100*$P28 -> 8.052 | G28: =IF($C28="","",VLOOKUP($C28,성분!$B$2:$O$1509,4,FALSE))/100*$P28 -> 0.888 | H28: =IF($C28="","",VLOOKUP($C28,성분!$B$2:$O$1509,6,FALSE))/100*$P28 -> 0.024 | I28: =IF($C28="","",VLOOKUP($C28,성분!$B$2:$O$1509,7,FALSE))/100*$P28 -> 21.6 | J28: =IF($C28="","",VLOOKUP($C28,성분!$B$2:$O$1509,8,FALSE))/100*$P28 -> 0.348 | K28: =IF($C28="","",VLOOKUP($C28,성분!$B$2:$O$1509,9,FALSE))/100*$P28 -> 0.96 | L28: =IF($C28="","",VLOOKUP($C28,성분!$B$2:$O$1509,10,FALSE))/100*$P28 -> 0.0084 | M28: =IF($C28="","",VLOOKUP($C28,성분!$B$2:$O$10517,11,FALSE))/100*$P28 -> 0.0504 | N28: =IF($C28="","",VLOOKUP($C28,성분!$B$2:$O$10517,12,FALSE))/100*$P28 -> 0.036 | O28: =IF($C28="","",VLOOKUP($C28,성분!$B$2:$O$10517,13,FALSE))/100*$P28 -> 0 | P28: =D28 -> 12 | Q28: =($O$8*P28)/1000 -> 1.272 | R28: =INT(Q28) -> 1
A29: 1인 기준량 | E29: =SUM(E11:E28) -> 875.79 | F29: =SUM(F11:F28) -> 156.9719 | G29: =SUM(G11:G28) -> 33.5693 | H29: =SUM(H11:H28) -> 19.326 | I29: =SUM(I11:I28) -> 108.01 | J29: =SUM(J11:J28) -> 2.7934 | K29: =SUM(K11:K28) -> 133.07 | L29: =SUM(L11:L28) -> 1.217 | ... O29: =SUM(O11:O28) -> 23.506 | P29: =D29 -> 0 | Q29: =($O$8*P29)/1000 -> 0 | R29: =INT(Q29) -> 0
A30: 급식모니터링, 대면검수 1. 맛 양호 2. 이물,이취 등 없음 3.조리상태 양호. | R30: =INT(Q30) -> 0
A31: ※식품원산지표기 | S31: =INT(R31) -> 0
A32: 쌀: 국내산 | P32: 1인 급식비 | R32: 5000
A33: 포기김치:배추(국내산) / 돼지고기(국내산) / 닭고기(국내산) / 식육가공품(국내산/외국산) | P33: 1인 식품비 | R33: =R32*0.72 -> 3600
P34: 비율 | R34: 0.72
G35: 667 | H35: 15 | I35: 300 | J35: 5.4 | K35: 234 | L35: 0.34 | M35: 0.4 | N35: 5.26 | O35: 33.4
D1345: 240

Sheet 2수
M1: 업체담당 | N1: 학교담당 | O1: 행정실장
M2: 정소예
A3: 일 자 : | C3: 45749 | E3: 석식
A6: 급식학생수 | O6: 총계
A7: 구분 | D7: 1학년 | F7: 2학년 | H7: 3학년 | K7: 합계 | M7: 교직원
A8: 심인고등학교 | D8: 0 | F8: 0 | H8: 107 | K8: =SUM(D8:J8) -> 107 | M8: 2 | O8: =K8+M8 -> 109
A9: 식 단 | D9: 잡곡밥,돈육김치찌개,마라찜닭,소시지구이&머스타드,치커리유자무침,깍두기&진한망고
A10: 번호 | B10: 메뉴명 | C10: 식품명 | D10: 1인량 (g) | E10: 열량 (kcal) | F10: 탄수화물 (g) | G10: 단백질 (g) | H10: 지방 (g) | I10: 칼슘 (mg) | J10: 철 (mg) | K10: VIT-A (RE) | L10: VIT-B1 (mg) | M10: VIT-B2 (mg) | N10: NIACIN (mg) | O10: VIT-C | P10: 기준량 | Q10: 총량
A11: =ROW()-10 -> 1 | B11: 잡곡밥 | C11: 잡곡 | D11: 4 | E11: =IF($C11="","",VLOOKUP($C11,성분!$B$2:$O$51519,3,FALSE))/100*P11 -> 13.96 | F11: =IF($C11="","",VLOOKUP($C11,성분!$B$2:$O$51519,5,FALSE))/100*$P11 -> 3 | G11: =IF($C11="","",VLOOKUP($C11,성분!$B$2:$O$51519,4,FALSE))/100*$P11 -> 0.392 | H11: =IF($C11="","",VLOOKUP($C11,성분!$B$2:$O$51519,6,FALSE))/100*$P11 -> 0.06 | I11: =IF($C11="","",VLOOKUP($C11,성분!$B$2:$O$51519,7,FALSE))/100*$P11 -> 0 | J11: =IF($C11="","",VLOOKUP($C11,성분!$B$2:$O$51519,8,FALSE))/100*$P11 -> 0 | K11: =IF($C11="","",VLOOKUP($C11,성분!$B$2:$O$51519,9,FALSE))/100*$P11 -> 0 | L11: =IF($C11="","",VLOOKUP($C11,성분!$B$2:$O$51519,10,FALSE))/100*$P11 -> 0.0088 | M11: =IF($C11="","",VLOOKUP($C11,성분!$B$2:$O$51519,11,FALSE))/100*$P11 -> 0.0036 | N11: =IF($C11="","",VLOOKUP($C11,성분!$B$2:$O$51519,12,FALSE))/100*$P11 -> 0 | O11: =IF($C11="","",VLOOKUP($C11,성분!$B$2:$O$51519,13,FALSE))/100*$P11 -> 0 | P11: =D11 -> 4 | Q11: =($O$8*P11)/1000 -> 0.436 | R11: =INT(Q11) -> 0
A12: =ROW()-10 -> 2 | C12: 쌀 | D12: 100 | E12: =IF($C12="","",VLOOKUP($C12,성분!$B$2:$O$51519,3,FALSE))/100*P12 -> 240 | F12: =IF($C12="","",VLOOKUP($C12,성분!$B$2:$O$51519,5,FALSE))/100*$P12 -> 78.5 | G12: =IF($C12="","",VLOOKUP($C12,성분!$B$2:$O$51519,4,FALSE))/100*$P12 -> 6.4 | H12: =IF($C12="","",VLOOKUP($C12,성분!$B$2:$O$51519,6,FALSE))/100*$P12 -> 0.4 | I12: =IF($C12="","",VLOOKUP($C12,성분!$B$2:$O$51519,7,FALSE))/100*$P12 -> 7 | J12: =IF($C12="","",VLOOKUP($C12,성분!$B$2:$O$51519,8,FALSE))/100*$P12 -> 0.5 | K12: =IF($C12="","",VLOOKUP($C12,성분!$B$2:$O$51519,9,FALSE))/100*$P12 -> 0 | L12: =IF($C12="","",VLOOKUP($C12,성분!$B$2:$O$51519,10,FALSE))/100*$P12 -> 0.12 | M12: =IF($C12="","",VLOOKUP($C12,성분!$B$2:$O$51519,11,FALSE))/100*$P12 -> 0 | N12: =IF($C12="","",VLOOKUP($C12,성분!$B$2:$O$51519,12,FALSE))/100*$P12 -> 1.4 | O12: =IF($C12="","",VLOOKUP($C12,성분!$B$2:$O$51519,13,FALSE))/100*$P12 -> 0 | P12: =D12 -> 100 | Q12: =($O$8*P12)/1000 -> 10.9 | R12: =INT(Q12) -> 10
A13: =ROW()-10 -> 3 | B13: 돈육김치찌개 | C13: 돈찌개 | D13: 20 | E13: =IF($C13="","",VLOOKUP($C13,성분!$B$2:$O$51519,3,FALSE))/100*P13 -> 24.6 | F13: =IF($C13="","",VLOOKUP($C13,성분!$B$2:$O$51519,5,FALSE))/100*$P13 -> 2.1 | G13: =IF($C13="","",VLOOKUP($C13,성분!$B$2:$O$51519,4,FALSE))/100*$P13 -> 1.44 | H13: =IF($C13="","",VLOOKUP($C13,성분!$B$2:$O$51519,6,FALSE))/100*$P13 -> 2.252 | I13: =IF($C13="","",VLOOKUP($C13,성분!$B$2:$O$51519,7,FALSE))/100*$P13 -> 0.2 | J13: =IF($C13="","",VLOOKUP($C13,성분!$B$2:$O$51519,8,FALSE))/100*$P13 -> 0.2 | K13: =IF($C13="","",VLOOKUP($C13,성분!$B$2:$O$51519,9,FALSE))/100*$P13 -> 3.2 | L13: =IF($C13="","",VLOOKUP($C13,성분!$B$2:$O$51519,10,FALSE))/100*$P13 -> 0.02 | M13: =IF($C13="","",VLOOKUP($C13,성분!$B$2:$O$51519,11,FALSE))/100*$P13 -> 0.016 | N13: =IF($C13="","",VLOOKUP($C13,성분!$B$2:$O$51519,12,FALSE))/100*$P13 -> 0.174 | O13: =IF($C13="","",VLOOKUP($C13,성분!$B$2:$O$51519,13,FALSE))/100*$P13 -> 0 | P13: =D13 -> 20 | Q13: =($O$8*P13)/1000 -> 2.18 | R13: =INT(Q13) -> 2
A14: =ROW()-10 -> 4 | C14: 맛김치 | D14: 25 | E14: =IF($C14="","",VLOOKUP($C14,성분!$B$2:$O$51519,3,FALSE))/100*P14 -> 12.5 | F14: =IF($C14="","",VLOOKUP($C14,성분!$B$2:$O$51519,5,FALSE))/100*$P14 -> 1.1 | G14: =IF($C14="","",VLOOKUP($C14,성분!$B$2:$O$51519,4,FALSE))/100*$P14 -> 0.5 | H14: =IF($C14="","",VLOOKUP($C14,성분!$B$2:$O$51519,6,FALSE))/100*$P14 -> 0.05 | I14: =IF($C14="","",VLOOKUP($C14,성분!$B$2:$O$51519,7,FALSE))/100*$P14 -> 11.75 | J14: =IF($C14="","",VLOOKUP($C14,성분!$B$2:$O$51519,8,FALSE))/100*$P14 -> 0.2 | K14: =IF($C14="","",VLOOKUP($C14,성분!$B$2:$O$51519,9,FALSE))/100*$P14 -> 12 | L14: =IF($C14="","",VLOOKUP($C14,성분!$B$2:$O$51519,10,FALSE))/100*$P14 -> 0.015 | M14: =IF($C14="","",VLOOKUP($C14,성분!$B$2:$O$51519,11,FALSE))/100*$P14 -> 0.015 | N14: =IF($C14="","",VLOOKUP($C14,성분!$B$2:$O$51519,12,FALSE))/100*$P14 -> 0.2 | O14: =IF($C14="","",VLOOKUP($C14,성분!$B$2:$O$51519,13,FALSE))/100*$P14 -> 3.5 | P14: =D14 -> 25 | Q14: =($O$8*P14)/1000 -> 2.725 | R14: =INT(Q14) -> 2
A15: =ROW()-10 -> 5 | C15: 두부 | D15: 20 | E15: =IF($C15="","",VLOOKUP($C15,성분!$B$2:$O$51519,3,FALSE))/100*P15 -> 15.8 | F15: =IF($C15="","",VLOOKUP($C15,성분!$B$2:$O$51519,5,FALSE))/100*$P15 -> 0.74 | G15: =IF($C15="","",VLOOKUP($C15,성분!$B$2:$O$51519,4,FALSE))/100*$P15 -> 1.68 | H15: =IF($C15="","",VLOOKUP($C15,성분!$B$2:$O$51519,6,FALSE))/100*$P15 -> 0.7 | I15: =IF($C15="","",VLOOKUP($C15,성분!$B$2:$O$51519,7,FALSE))/100*$P15 -> 31.8 | J15: =IF($C15="","",VLOOKUP($C15,성분!$B$2:$O$51519,8,FALSE))/100*$P15 -> 0.52 | K15: =IF($C15="","",VLOOKUP($C15,성분!$B$2:$O$51519,9,FALSE))/100*$P15 -> 0 | L15: =IF($C15="","",VLOOKUP($C15,성분!$B$2:$O$51519,10,FALSE))/100*$P15 -> 0.01 | M15: =IF($C15="","",VLOOKUP($C15,성분!$B$2:$O$51519,11,FALSE))/100*$P15 -> 0.008 | N15: =IF($C15="","",VLOOKUP($C15,성분!$B$2:$O$51519,12,FALSE))/100*$P15 -> 0.14 | O15: =IF($C15="","",VLOOKUP($C15,성분!$B$2:$O$51519,13,FALSE))/100*$P15 -> 0 | P15: =D15 -> 20 | Q15: =($O$8*P15)/1000 -> 2.18 | R15: =INT(Q15) -> 2
A16: =ROW()-10 -> 6 | C16: 무우 | D16: 30 | E16: =IF($C16="","",VLOOKUP($C16,성분!$B$2:$O$51519,3,FALSE))/100*P16 -> 5.4 | F16: =IF($C16="","",VLOOKUP($C16,성분!$B$2:$O$51519,5,FALSE))/100*$P16 -> 1.254 | G16: =IF($C16="","",VLOOKUP($C16,성분!$B$2:$O$51519,4,FALSE))/100*$P16 -> 0.24 | H16: =IF($C16="","",VLOOKUP($C16,성분!$B$2:$O$51519,6,FALSE))/100*$P16 -> 0.06 | I16: =IF($C16="","",VLOOKUP($C16,성분!$B$2:$O$51519,7,FALSE))/100*$P16 -> 7.5 | J16: =IF($C16="","",VLOOKUP($C16,성분!$B$2:$O$51519,8,FALSE))/100*$P16 -> 0.234 | K16: =IF($C16="","",VLOOKUP($C16,성분!$B$2:$O$51519,9,FALSE))/100*$P16 -> 4.5 | L16: =IF($C16="","",VLOOKUP($C16,성분!$B$2:$O$51519,10,FALSE))/100*$P16 -> 0.009 | M16: =IF($C16="","",VLOOKUP($C16,성분!$B$2:$O$51519,11,FALSE))/100*$P16 -> 0.018 | N16: =IF($C16="","",VLOOKUP($C16,성분!$B$2:$O$51519,12,FALSE))/100*$P16 -> 0.063 | O16: =IF($C16="","",VLOOKUP($C16,성분!$B$2:$O$51519,13,FALSE))/100*$P16 -> 0.96 | P16: =D16 -> 30 | Q16: =($O$8*P16)/1000 -> 3.27 | R16: =INT(Q16) -> 3
A17: =ROW()-10 -> 7 | C17: 양파 | D17: 15 | E17: =IF($C17="","",VLOOKUP($C17,성분!$B$2:$O$51519,3,FALSE))/100*P17 -> 5.25 | F17: =IF($C17="","",VLOOKUP($C17,성분!$B$2:$O$51519,5,FALSE))/100*$P17 -> 1.149 | G17: =IF($C17="","",VLOOKUP($C17,성분!$B$2:$O$51519,4,FALSE))/100*$P17 -> 0.15 | H17: =IF($C17="","",VLOOKUP($C17,성분!$B$2:$O$51519,6,FALSE))/100*$P17 -> 0.0285 | I17: =IF($C17="","",VLOOKUP($C17,성분!$B$2:$O$51519,7,FALSE))/100*$P17 -> 2.25 | J17: =IF($C17="","",VLOOKUP($C17,성분!$B$2:$O$51519,8,FALSE))/100*$P17 -> 0.045 | K17: =IF($C17="","",VLOOKUP($C17,성분!$B$2:$O$51519,9,FALSE))/100*$P17 -> 0 | L17: =IF($C17="","",VLOOKUP($C17,성분!$B$2:$O$51519,10,FALSE))/100*$P17 -> 0.006 | M17: =IF($C17="","",VLOOKUP($C17,성분!$B$2:$O$51519,11,FALSE))/100*$P17 -> 0.0015 | N17: =IF($C17="","",VLOOKUP($C17,성분!$B$2:$O$51519,12,FALSE))/100*$P17 -> 0.03 | O17: =IF($C17="","",VLOOKUP($C17,성분!$B$2:$O$51519,13,FALSE))/100*$P17 -> 1.2 | P17: =D17 -> 15 | Q17: =($O$8*P17)/1000 -> 1.635 | R17: =INT(Q17) -> 1
A18: =ROW()-10 -> 8 | C18: 대파 | D18: 5 | E18: =IF($C18="","",VLOOKUP($C18,성분!$B$2:$O$51519,3,FALSE))/100*P18 -> 1.3 | F18: =IF($C18="","",VLOOKUP($C18,성분!$B$2:$O$51519,5,FALSE))/100*$P18 -> 0.223 | G18: =IF($C18="","",VLOOKUP($C18,성분!$B$2:$O$51519,4,FALSE))/100*$P18 -> 0 | H18: =IF($C18="","",VLOOKUP($C18,성분!$B$2:$O$51519,6,FALSE))/100*$P18 -> 0.013 | I18: =IF($C18="","",VLOOKUP($C18,성분!$B$2:$O$51519,7,FALSE))/100*$P18 -> 4.05 | J18: =IF($C18="","",VLOOKUP($C18,성분!$B$2:$O$51519,8,FALSE))/100*$P18 -> 0.05 | K18: =IF($C18="","",VLOOKUP($C18,성분!$B$2:$O$51519,9,FALSE))/100*$P18 -> 6.45 | L18: =IF($C18="","",VLOOKUP($C18,성분!$B$2:$O$51519,10,FALSE))/100*$P18 -> 0.003 | M18: =IF($C18="","",VLOOKUP($C18,성분!$B$2:$O$51519,11,FALSE))/100*$P18 -> 0.0045 | N18: =IF($C18="","",VLOOKUP($C18,성분!$B$2:$O$51519,12,FALSE))/100*$P18 -> 0.03 | O18: =IF($C18="","",VLOOKUP($C18,성분!$B$2:$O$51519,13,FALSE))/100*$P18 -> 1.05 | P18: =D18 -> 5 | Q18: =($O$8*P18)/1000 -> 0.545 | R18: =INT(Q18) -> 0
A19: =ROW()-10 -> 9 | C19: 건다시마 | D19: 3 | E19: =IF($C19="","",VLOOKUP($C19,성분!$B$2:$O$51519,3,FALSE))/100*P19 -> 5.67 | F19: =IF($C19="","",VLOOKUP($C19,성분!$B$2:$O$51519,5,FALSE))/100*$P19 -> 1.356 | G19: =IF($C19="","",VLOOKUP($C19,성분!$B$2:$O$51519,4,FALSE))/100*$P19 -> 0.222 | H19: =IF($C19="","",VLOOKUP($C19,성분!$B$2:$O$51519,6,FALSE))/100*$P19 -> 0.033 | I19: =IF($C19="","",VLOOKUP($C19,성분!$B$2:$O$51519,7,FALSE))/100*$P19 -> 21.24 | J19: =IF($C19="","",VLOOKUP($C19,성분!$B$2:$O$51519,8,FALSE))/100*$P19 -> 0.189 | K19: =IF($C19="","",VLOOKUP($C19,성분!$B$2:$O$51519,9,FALSE))/100*$P19 -> 2.88 | L19: =IF($C19="","",VLOOKUP($C19,성분!$B$2:$O$51519,10,FALSE))/100*$P19 -> 0.0066 | M19: =IF($C19="","",VLOOKUP($C19,성분!$B$2:$O$51519,11,FALSE))/100*$P19 -> 0.0135 | N19: =IF($C19="","",VLOOKUP($C19,성분!$B$2:$O$51519,12,FALSE))/100*$P19 -> 0.135 | O19: =IF($C19="","",VLOOKUP($C19,성분!$B$2:$O$51519,13,FALSE))/100*$P19 -> 0.54 | P19: =D19 -> 3 | Q19: =($O$8*P19)/1000 -> 0.327 | R19: =INT(Q19) -> 0
A20: =ROW()-10 -> 10 | C20: 다시멸치 | D20: 3 | E20: =IF($C20="","",VLOOKUP($C20,성분!$B$2:$O$51519,3,FALSE))/100*P20 -> 9.09 | F20: =IF($C20="","",VLOOKUP($C20,성분!$B$2:$O$51519,5,FALSE))/100*$P20 -> 0.009 | G20: =IF($C20="","",VLOOKUP($C20,성분!$B$2:$O$51519,4,FALSE))/100*$P20 -> 0.99 | H20: =IF($C20="","",VLOOKUP($C20,성분!$B$2:$O$51519,6,FALSE))/100*$P20 -> 0.219 | I20: =IF($C20="","",VLOOKUP($C20,성분!$B$2:$O$51519,7,FALSE))/100*$P20 -> 51 | J20: =IF($C20="","",VLOOKUP($C20,성분!$B$2:$O$51519,8,FALSE))/100*$P20 -> 0.12 | K20: =IF($C20="","",VLOOKUP($C20,성분!$B$2:$O$51519,9,FALSE))/100*$P20 -> 0 | L20: =IF($C20="","",VLOOKUP($C20,성분!$B$2:$O$51519,10,FALSE))/100*$P20 -> 0.0042 | M20: =IF($C20="","",VLOOKUP($C20,성분!$B$2:$O$51519,11,FALSE))/100*$P20 -> 0.0036 | N20: =IF($C20="","",VLOOKUP($C20,성분!$B$2:$O$51519,12,FALSE))/100*$P20 -> 0.06 | O20: =IF($C20="","",VLOOKUP($C20,성분!$B$2:$O$51519,13,FALSE))/100*$P20 -> 0 | P20: =D20 -> 3 | Q20: =($O$8*P20)/1000 -> 0.327 | R20: =INT(Q20) -> 0
A21: =ROW()-10 -> 11 | B21: 마라찜닭 | C21: 닭정육 | D21: 70 | E21: =IF($C21="","",VLOOKUP($C21,성분!$B$2:$O$51519,3,FALSE))/100*P21 -> 71.4 | F21: =IF($C21="","",VLOOKUP($C21,성분!$B$2:$O$51519,5,FALSE))/100*$P21 -> 0 | G21: =IF($C21="","",VLOOKUP($C21,성분!$B$2:$O$51519,4,FALSE))/100*$P21 -> 8.022 | H21: =IF($C21="","",VLOOKUP($C21,성분!$B$2:$O$51519,6,FALSE))/100*$P21 -> 8.953 | I21: =IF($C21="","",VLOOKUP($C21,성분!$B$2:$O$51519,7,FALSE))/100*$P21 -> 4.389 | J21: =IF($C21="","",VLOOKUP($C21,성분!$B$2:$O$51519,8,FALSE))/100*$P21 -> 0.399 | K21: =IF($C21="","",VLOOKUP($C21,성분!$B$2:$O$51519,9,FALSE))/100*$P21 -> 5.985 | L21: =IF($C21="","",VLOOKUP($C21,성분!$B$2:$O$51519,10,FALSE))/100*$P21 -> 0.035 | M21: =IF($C21="","",VLOOKUP($C21,성분!$B$2:$O$51519,11,FALSE))/100*$P21 -> 0.077 | N21: =IF($C21="","",VLOOKUP($C21,성분!$B$2:$O$51519,12,FALSE))/100*$P21 -> 0 | O21: =IF($C21="","",VLOOKUP($C21,성분!$B$2:$O$51519,13,FALSE))/100*$P21 -> 0.497 | P21: =D21 -> 70 | Q21: =($O$8*P21)/1000 -> 7.63 | R21: =INT(Q21) -> 7
A22: =ROW()-10 -> 12 | C22: 닭안심 | D22: 50 | E22: =IF($C22="","",VLOOKUP($C22,성분!$B$2:$O$51519,3,FALSE))/100*P22 -> 57.5 | F22: =IF($C22="","",VLOOKUP($C22,성분!$B$2:$O$51519,5,FALSE))/100*$P22 -> 0.05 | G22: =IF($C22="","",VLOOKUP($C22,성분!$B$2:$O$51519,4,FALSE))/100*$P22 -> 12 | H22: =IF($C22="","",VLOOKUP($C22,성분!$B$2:$O$51519,6,FALSE))/100*$P22 -> 0.7 | I22: =IF($C22="","",VLOOKUP($C22,성분!$B$2:$O$51519,7,FALSE))/100*$P22 -> 5.5 | J22: =IF($C22="","",VLOOKUP($C22,성분!$B$2:$O$51519,8,FALSE))/100*$P22 -> 0.55 | K22: =IF($C22="","",VLOOKUP($C22,성분!$B$2:$O$51519,9,FALSE))/100*$P22 -> 0 | L22: =IF($C22="","",VLOOKUP($C22,성분!$B$2:$O$51519,10,FALSE))/100*$P22 -> 0.1 | M22: =IF($C22="","",VLOOKUP($C22,성분!$B$2:$O$51519,11,FALSE))/100*$P22 -> 0.105 | N22: =IF($C22="","",VLOOKUP($C22,성분!$B$2:$O$51519,12,FALSE))/100*$P22 -> 1.45 | O22: =IF($C22="","",VLOOKUP($C22,성분!$B$2:$O$51519,13,FALSE))/100*$P22 -> 0 | P22: =D22 -> 50 | Q22: =($O$8*P22)/1000 -> 5.45 | R22: =INT(Q22) -> 5
A23: =ROW()-10 -> 13 | C23: 고구마 | D23: 15 | E23: =IF($C23="","",VLOOKUP($C23,성분!$B$2:$O$51519,3,FALSE))/100*P23 -> 19.2 | F23: =IF($C23="","",VLOOKUP($C23,성분!$B$2:$O$51519,5,FALSE))/100*$P23 -> 4.65 | G23: =IF($C23="","",VLOOKUP($C23,성분!$B$2:$O$51519,4,FALSE))/100*$P23 -> 0.21 | H23: =IF($C23="","",VLOOKUP($C23,성분!$B$2:$O$51519,6,FALSE))/100*$P23 -> 0.0285 | I23: =IF($C23="","",VLOOKUP($C23,성분!$B$2:$O$51519,7,FALSE))/100*$P23 -> 3.6 | J23: =IF($C23="","",VLOOKUP($C23,성분!$B$2:$O$51519,8,FALSE))/100*$P23 -> 0.075 | K23: =IF($C23="","",VLOOKUP($C23,성분!$B$2:$O$51519,9,FALSE))/100*$P23 -> 2.85 | L23: =IF($C23="","",VLOOKUP($C23,성분!$B$2:$O$51519,10,FALSE))/100*$P23 -> 0.009 | M23: =IF($C23="","",VLOOKUP($C23,성분!$B$2:$O$51519,11,FALSE))/100*$P23 -> 0.0075 | N23: =IF($C23="","",VLOOKUP($C23,성분!$B$2:$O$51519,12,FALSE))/100*$P23 -> 0.105 | O23: =IF($C23="","",VLOOKUP($C23,성분!$B$2:$O$51519,13,FALSE))/100*$P23 -> 3.75 | P23: =D23 -> 15 | Q23: =($O$8*P23)/1000 -> 1.635 | R23: =INT(Q23) -> 1
A24: =ROW()-10 -> 14 | C24: 분모자 | D24: 10 | E24: =IF($C24="","",VLOOKUP($C24,성분!$B$2:$O$51519,3,FALSE))/100*P24 -> 19.04 | F24: =IF($C24="","",VLOOKUP($C24,성분!$B$2:$O$51519,5,FALSE))/100*$P24 -> 8.5 | G24: =IF($C24="","",VLOOKUP($C24,성분!$B$2:$O$51519,4,FALSE))/100*$P24 -> 0.01 | H24: =IF($C24="","",VLOOKUP($C24,성분!$B$2:$O$51519,6,FALSE))/100*$P24 -> 0.02 | I24: =IF($C24="","",VLOOKUP($C24,성분!$B$2:$O$51519,7,FALSE))/100*$P24 -> 4.7 | J24: =IF($C24="","",VLOOKUP($C24,성분!$B$2:$O$51519,8,FALSE))/100*$P24 -> 0.3 | K24: =IF($C24="","",VLOOKUP($C24,성분!$B$2:$O$51519,9,FALSE))/100*$P24 -> 0 | L24: =IF($C24="","",VLOOKUP($C24,성분!$B$2:$O$51519,10,FALSE))/100*$P24 -> 0.001 | M24: =IF($C24="","",VLOOKUP($C24,성분!$B$2:$O$51519,11,FALSE))/100*$P24 -> 0 | N24: =IF($C24="","",VLOOKUP($C24,성분!$B$2:$O$51519,12,FALSE))/100*$P24 -> 0 | O24: =IF($C24="","",VLOOKUP($C24,성분!$B$2:$O$51519,13,FALSE))/100*$P24 -> 0 | P24: =D24 -> 10 | Q24: =($O$8*P24)/1000 -> 1.09 | R24: =INT(Q24) -> 1
